Workbook

Sheet vw
A2: mul_cil_a2
A3: No | B3: Run | C3: 1 | H3: 2 | M3: 3 | R3: 4 | W3: 5
B4: Task | C4: 100k | D4: 200k | E4: 300k | F4: 400k | G4: 500k | H4: 100k | I4: 200k | J4: 300k | K4: 400k | L4: 500k | M4: 100k | N4: 200k | O4: 300k | P4: 400k | Q4: 500k | R4: 100k | S4: 200k | T4: 300k | U4: 400k | V4: 500k | W4: 100k | X4: 200k | Y4: 300k | Z4: 400k | AA4: 500k
C5: success (1)/ No Success (0) | D5: success (1)/ No Success (0) | E5: success (1)/ No Success (0) | F5: success (1)/ No Success (0) | G5: success (1)/ No Success (0) | H5: success (1)/ No Success (0) | I5: success (1)/ No Success (0) | J5: success (1)/ No Success (0) | K5: success (1)/ No Success (0) | L5: success (1)/ No Success (0) | M5: success (1)/ No Success (0) | N5: success (1)/ No Success (0) | O5: success (1)/ No Success (0) | P5: success (1)/ No Success (0) | Q5: success (1)/ No Success (0) | R5: success (1)/ No Success (0) | S5: success (1)/ No Success (0) | T5: success (1)/ No Success (0) | U5: success (1)/ No Success (0) | V5: success (1)/ No Success (0) | W5: success (1)/ No Success (0) | X5: success (1)/ No Success (0) | Y5: success (1)/ No Success (0) | Z5: success (1)/ No Success (0) | AA5: success (1)/ No Success (0)
A6: 1 | B6: straight | C6: =INDIRECT("'[CILA2_Validation_Files.xlsx]"&$A$2&"_"&$C$3&"_"&COLUMN(A$2)*100&"k_"&MID(CELL("filename",A1),FIND("]",CELL("filename",A1))+1,255)&"_"&$B$6&"'!H"&ROW(A2)) -> 1 | D6: =INDIRECT("'[CILA2_Validation_Files.xlsx]"&$A$2&"_"&$C$3&"_"&COLUMN(B$2)*100&"k_"&MID(CELL("filename",B1),FIND("]",CELL("filename",B1))+1,255)&"_"&$B$6&"'!H"&ROW(B2)) -> 1 | E6: =INDIRECT("'[CILA2_Validation_Files.xlsx]"&$A$2&"_"&$C$3&"_"&COLUMN(C$2)*100&"k_"&MID(CELL("filename",C1),FIND("]",CELL("filename",C1))+1,255)&"_"&$B$6&"'!H"&ROW(C2)) -> 1 | F6: =INDIRECT("'[CILA2_Validation_Files.xlsx]"&$A$2&"_"&$C$3&"_"&COLUMN(D$2)*100&"k_"&MID(CELL("filename",D1),FIND("]",CELL("filename",D1))+1,255)&"_"&$B$6&"'!H"&ROW(D2)) -> 1 | G6: =INDIRECT("'[CILA2_Validation_Files.xlsx]"&$A$2&"_"&$C$3&"_"&COLUMN(E$2)*100&"k_"&MID(CELL("filename",E1),FIND("]",CELL("filename",E1))+1,255)&"_"&$B$6&"'!H"&ROW(E2)) -> 1 | H6: =INDIRECT("'[CILA2_Validation_Files.xlsx]"&$A$2&"_"&$H$3&"_"&COLUMN(A$2)*100&"k_"&MID(CELL("filename",A1),FIND("]",CELL("filename",A1))+1,255)&"_"&$B$6&"'!H"&ROW(A2)) -> 1 | I6: =INDIRECT("'[CILA2_Validation_Files.xlsx]"&$A$2&"_"&$H$3&"_"&COLUMN(B$2)*100&"k_"&MID(CELL("filename",B1),FIND("]",CELL("filename",B1))+1,255)&"_"&$B$6&"'!H"&ROW(B2)) -> 1 | J6: =INDIRECT("'[CILA2_Validation_Files.xlsx]"&$A$2&"_"&$H$3&"_"&COLUMN(C$2)*100&"k_"&MID(CELL("filename",C1),FIND("]",CELL("filename",C1))+1,255)&"_"&$B$6&"'!H"&ROW(C2)) -> 1 | K6: =INDIRECT("'[CILA2_Validation_Files.xlsx]"&$A$2&"_"&$H$3&"_"&COLUMN(D$2)*100&"k_"&MID(CELL("filename",D1),FIND("]",CELL("filename",D1))+1,255)&"_"&$B$6&"'!H"&ROW(D2)) -> 1 | L6: =INDIRECT("'[CILA2_Validation_Files.xlsx]"&$A$2&"_"&$H$3&"_"&COLUMN(E$2)*100&"k_"&MID(CELL("filename",E1),FIND("]",CELL("filename",E1))+1,255)&"_"&$B$6&"'!H"&ROW(E2)) -> 1 | M6: =INDIRECT("'[CILA2_Validation_Files.xlsx]"&$A$2&"_"&$M$3&"_"&COLUMN(A$2)*100&"k_"&MID(CELL("filename",A1),FIND("]",CELL("filename",A1))+1,255)&"_"&$B$6&"'!H"&ROW(A2)) -> 1 | N6: =INDIRECT("'[CILA2_Validation_Files.xlsx]"&$A$2&"_"&$M$3&"_"&COLUMN(B$2)*100&"k_"&MID(CELL("filename",B1),FIND("]",CELL("filename",B1))+1,255)&"_"&$B$6&"'!H"&ROW(B2)) -> 1 | O6: =INDIRECT("'[CILA2_Validation_Files.xlsx]"&$A$2&"_"&$M$3&"_"&COLUMN(C$2)*100&"k_"&MID(CELL("filename",C1),FIND("]",CELL("filename",C1))+1,255)&"_"&$B$6&"'!H"&ROW(C2)) -> 1 | P6: =INDIRECT("'[CILA2_Validation_Files.xlsx]"&$A$2&"_"&$M$3&"_"&COLUMN(D$2)*100&"k_"&MID(CELL("filename",D1),FIND("]",CELL("filename",D1))+1,255)&"_"&$B$6&"'!H"&ROW(D2)) -> 1 | Q6: =INDIRECT("'[CILA2_Validation_Files.xlsx]"&$A$2&"_"&$M$3&"_"&COLUMN(E$2)*100&"k_"&MID(CELL("filename",E1),FIND("]",CELL("filename",E1))+1,255)&"_"&$B$6&"'!H"&ROW(E2)) -> 1 | R6: =INDIRECT("'[CILA2_Validation_Files.xlsx]"&$A$2&"_"&$R$3&"_"&COLUMN(A$2)*100&"k_"&MID(CELL("filename",A1),FIND("]",CELL("filename",A1))+1,255)&"_"&$B$6&"'!H"&ROW(A2)) -> 1 | S6: =INDIRECT("'[CILA2_Validation_Files.xlsx]"&$A$2&"_"&$R$3&"_"&COLUMN(B$2)*100&"k_"&MID(CELL("filename",B1),FIND("]",CELL("filename",B1))+1,255)&"_"&$B$6&"'!H"&ROW(B2)) -> 1 | T6: =INDIRECT("'[CILA2_Validation_Files.xlsx]"&$A$2&"_"&$R$3&"_"&COLUMN(C$2)*100&"k_"&MID(CELL("filename",C1),FIND("]",CELL("filename",C1))+1,255)&"_"&$B$6&"'!H"&ROW(C2)) -> 1 | U6: =INDIRECT("'[CILA2_Validation_Files.xlsx]"&$A$2&"_"&$R$3&"_"&COLUMN(D$2)*100&"k_"&MID(CELL("filename",D1),FIND("]",CELL("filename",D1))+1,255)&"_"&$B$6&"'!H"&ROW(D2)) -> 1 | V6: =INDIRECT("'[CILA2_Validation_Files.xlsx]"&$A$2&"_"&$R$3&"_"&COLUMN(E$2)*100&"k_"&MID(CELL("filename",E1),FIND("]",CELL("filename",E1))+1,255)&"_"&$B$6&"'!H"&ROW(E2)) -> 1 | W6: =INDIRECT("'[CILA2_Validation_Files.xlsx]"&$A$2&"_"&$W$3&"_"&COLUMN(A$2)*100&"k_"&MID(CELL("filename",A1),FIND("]",CELL("filename",A1))+1,255)&"_"&$B$6&"'!H"&ROW(A2)) -> 1 | X6: =INDIRECT("'[CILA2_Validation_Files.xlsx]"&$A$2&"_"&$W$3&"_"&COLUMN(B$2)*100&"k_"&MID(CELL("filename",B1),FIND("]",CELL("filename",B1))+1,255)&"_"&$B$6&"'!H"&ROW(B2)) -> 1 | Y6: =INDIRECT("'[CILA2_Validation_Files.xlsx]"&$A$2&"_"&$W$3&"_"&COLUMN(C$2)*100&"k_"&MID(CELL("filename",C1),FIND("]",CELL("filename",C1))+1,255)&"_"&$B$6&"'!H"&ROW(C2)) -> 1 | Z6: =INDIRECT("'[CILA2_Validation_Files.xlsx]"&$A$2&"_"&$W$3&"_"&COLUMN(D$2)*100&"k_"&MID(CELL("filename",D1),FIND("]",CELL("filename",D1))+1,255)&"_"&$B$6&"'!H"&ROW(D2)) -> 1 | AA6: =INDIRECT("'[CILA2_Validation_Files.xlsx]"&$A$2&"_"&$W$3&"_"&COLUMN(E$2)*100&"k_"&MID(CELL("filename",E1),FIND("]",CELL("filename",E1))+1,255)&"_"&$B$6&"'!H"&ROW(E2)) -> 1 | AB6: =AVERAGE(C6:AA11) -> 1
A7: 2 | C7: =INDIRECT("'[CILA2_Validation_Files.xlsx]"&$A$2&"_"&$C$3&"_"&COLUMN(A$2)*100&"k_"&MID(CELL("filename",A2),FIND("]",CELL("filename",A2))+1,255)&"_"&$B$6&"'!H"&ROW(A3)) -> 1 | D7: =INDIRECT("'[CILA2_Validation_Files.xlsx]"&$A$2&"_"&$C$3&"_"&COLUMN(B$2)*100&"k_"&MID(CELL("filename",B2),FIND("]",CELL("filename",B2))+1,255)&"_"&$B$6&"'!H"&ROW(B3)) -> 1 | E7: =INDIRECT("'[CILA2_Validation_Files.xlsx]"&$A$2&"_"&$C$3&"_"&COLUMN(C$2)*100&"k_"&MID(CELL("filename",C2),FIND("]",CELL("filename",C2))+1,255)&"_"&$B$6&"'!H"&ROW(C3)) -> 1 | F7: =INDIRECT("'[CILA2_Validation_Files.xlsx]"&$A$2&"_"&$C$3&"_"&COLUMN(D$2)*100&"k_"&MID(CELL("filename",D2),FIND("]",CELL("filename",D2))+1,255)&"_"&$B$6&"'!H"&ROW(D3)) -> 1 | G7: =INDIRECT("'[CILA2_Validation_Files.xlsx]"&$A$2&"_"&$C$3&"_"&COLUMN(E$2)*100&"k_"&MID(CELL("filename",E2),FIND("]",CELL("filename",E2))+1,255)&"_"&$B$6&"'!H"&ROW(E3)) -> 1 | H7: =INDIRECT("'[CILA2_Validation_Files.xlsx]"&$A$2&"_"&$H$3&"_"&COLUMN(A$2)*100&"k_"&MID(CELL("filename",A2),FIND("]",CELL("filename",A2))+1,255)&"_"&$B$6&"'!H"&ROW(A3)) -> 1 | I7: =INDIRECT("'[CILA2_Validation_Files.xlsx]"&$A$2&"_"&$H$3&"_"&COLUMN(B$2)*100&"k_"&MID(CELL("filename",B2),FIND("]",CELL("filename",B2))+1,255)&"_"&$B$6&"'!H"&ROW(B3)) -> 1 | J7: =INDIRECT("'[CILA2_Validation_Files.xlsx]"&$A$2&"_"&$H$3&"_"&COLUMN(C$2)*100&"k_"&MID(CELL("filename",C2),FIND("]",CELL("filename",C2))+1,255)&"_"&$B$6&"'!H"&ROW(C3)) -> 1 | K7: =INDIRECT("'[CILA2_Validation_Files.xlsx]"&$A$2&"_"&$H$3&"_"&COLUMN(D$2)*100&"k_"&MID(CELL("filename",D2),FIND("]",CELL("filename",D2))+1,255)&"_"&$B$6&"'!H"&ROW(D3)) -> 1 | L7: =INDIRECT("'[CILA2_Validation_Files.xlsx]"&$A$2&"_"&$H$3&"_"&COLUMN(E$2)*100&"k_"&MID(CELL("filename",E2),FIND("]",CELL("filename",E2))+1,255)&"_"&$B$6&"'!H"&ROW(E3)) -> 1 | M7: =INDIRECT("'[CILA2_Validation_Files.xlsx]"&$A$2&"_"&$M$3&"_"&COLUMN(A$2)*100&"k_"&MID(CELL("filename",A2),FIND("]",CELL("filename",A2))+1,255)&"_"&$B$6&"'!H"&ROW(A3)) -> 1 | N7: =INDIRECT("'[CILA2_Validation_Files.xlsx]"&$A$2&"_"&$M$3&"_"&COLUMN(B$2)*100&"k_"&MID(CELL("filename",B2),FIND("]",CELL("filename",B2))+1,255)&"_"&$B$6&"'!H"&ROW(B3)) -> 1 | O7: =INDIRECT("'[CILA2_Validation_Files.xlsx]"&$A$2&"_"&$M$3&"_"&COLUMN(C$2)*100&"k_"&MID(CELL("filename",C2),FIND("]",CELL("filename",C2))+1,255)&"_"&$B$6&"'!H"&ROW(C3)) -> 1 | P7: =INDIRECT("'[CILA2_Validation_Files.xlsx]"&$A$2&"_"&$M$3&"_"&COLUMN(D$2)*100&"k_"&MID(CELL("filename",D2),FIND("]",CELL("filename",D2))+1,255)&"_"&$B$6&"'!H"&ROW(D3)) -> 1 | Q7: =INDIRECT("'[CILA2_Validation_Files.xlsx]"&$A$2&"_"&$M$3&"_"&COLUMN(E$2)*100&"k_"&MID(CELL("filename",E2),FIND("]",CELL("filename",E2))+1,255)&"_"&$B$6&"'!H"&ROW(E3)) -> 1 | R7: =INDIRECT("'[CILA2_Validation_Files.xlsx]"&$A$2&"_"&$R$3&"_"&COLUMN(A$2)*100&"k_"&MID(CELL("filename",A2),FIND("]",CELL("filename",A2))+1,255)&"_"&$B$6&"'!H"&ROW(A3)) -> 1 | S7: =INDIRECT("'[CILA2_Validation_Files.xlsx]"&$A$2&"_"&$R$3&"_"&COLUMN(B$2)*100&"k_"&MID(CELL("filename",B2),FIND("]",CELL("filename",B2))+1,255)&"_"&$B$6&"'!H"&ROW(B3)) -> 1 | T7: =INDIRECT("'[CILA2_Validation_Files.xlsx]"&$A$2&"_"&$R$3&"_"&COLUMN(C$2)*100&"k_"&MID(CELL("filename",C2),FIND("]",CELL("filename",C2))+1,255)&"_"&$B$6&"'!H"&ROW(C3)) -> 1 | U7: =INDIRECT("'[CILA2_Validation_Files.xlsx]"&$A$2&"_"&$R$3&"_"&COLUMN(D$2)*100&"k_"&MID(CELL("filename",D2),FIND("]",CELL("filename",D2))+1,255)&"_"&$B$6&"'!H"&ROW(D3)) -> 1 | V7: =INDIRECT("'[CILA2_Validation_Files.xlsx]"&$A$2&"_"&$R$3&"_"&COLUMN(E$2)*100&"k_"&MID(CELL("filename",E2),FIND("]",CELL("filename",E2))+1,255)&"_"&$B$6&"'!H"&ROW(E3)) -> 1 | W7: =INDIRECT("'[CILA2_Validation_Files.xlsx]"&$A$2&"_"&$W$3&"_"&COLUMN(A$2)*100&"k_"&MID(CELL("filename",A2),FIND("]",CELL("filename",A2))+1,255)&"_"&$B$6&"'!H"&ROW(A3)) -> 1 | X7: =INDIRECT("'[CILA2_Validation_Files.xlsx]"&$A$2&"_"&$W$3&"_"&COLUMN(B$2)*100&"k_"&MID(CELL("filename",B2),FIND("]",CELL("filename",B2))+1,255)&"_"&$B$6&"'!H"&ROW(B3)) -> 1 | Y7: =INDIRECT("'[CILA2_Validation_Files.xlsx]"&$A$2&"_"&$W$3&"_"&COLUMN(C$2)*100&"k_"&MID(CELL("filename",C2),FIND("]",CELL("filename",C2))+1,255)&"_"&$B$6&"'!H"&ROW(C3)) -> 1 | Z7: =INDIRECT("'[CILA2_Validation_Files.xlsx]"&$A$2&"_"&$W$3&"_"&COLUMN(D$2)*100&"k_"&MID(CELL("filename",D2),FIND("]",CELL("filename",D2))+1,255)&"_"&$B$6&"'!H"&ROW(D3)) -> 1 | AA7: =INDIRECT("'[CILA2_Validation_Files.xlsx]"&$A$2&"_"&$W$3&"_"&COLUMN(E$2)*100&"k_"&MID(CELL("filename",E2),FIND("]",CELL("filename",E2))+1,255)&"_"&$B$6&"'!H"&ROW(E3)) -> 1
A8: 3 | C8: =INDIRECT("'[CILA2_Validation_Files.xlsx]"&$A$2&"_"&$C$3&"_"&COLUMN(A$2)*100&"k_"&MID(CELL("filename",A3),FIND("]",CELL("filename",A3))+1,255)&"_"&$B$6&"'!H"&ROW(A4)) -> 1 | D8: =INDIRECT("'[CILA2_Validation_Files.xlsx]"&$A$2&"_"&$C$3&"_"&COLUMN(B$2)*100&"k_"&MID(CELL("filename",B3),FIND("]",CELL("filename",B3))+1,255)&"_"&$B$6&"'!H"&ROW(B4)) -> 1 | E8: =INDIRECT("'[CILA2_Validation_Files.xlsx]"&$A$2&"_"&$C$3&"_"&COLUMN(C$2)*100&"k_"&MID(CELL("filename",C3),FIND("]",CELL("filename",C3))+1,255)&"_"&$B$6&"'!H"&ROW(C4)) -> 1 | F8: =INDIRECT("'[CILA2_Validation_Files.xlsx]"&$A$2&"_"&$C$3&"_"&COLUMN(D$2)*100&"k_"&MID(CELL("filename",D3),FIND("]",CELL("filename",D3))+1,255)&"_"&$B$6&"'!H"&ROW(D4)) -> 1 | G8: =INDIRECT("'[CILA2_Validation_Files.xlsx]"&$A$2&"_"&$C$3&"_"&COLUMN(E$2)*100&"k_"&MID(CELL("filename",E3),FIND("]",CELL("filename",E3))+1,255)&"_"&$B$6&"'!H"&ROW(E4)) -> 1 | H8: =INDIRECT("'[CILA2_Validation_Files.xlsx]"&$A$2&"_"&$H$3&"_"&COLUMN(A$2)*100&"k_"&MID(CELL("filename",A3),FIND("]",CELL("filename",A3))+1,255)&"_"&$B$6&"'!H"&ROW(A4)) -> 1 | I8: =INDIRECT("'[CILA2_Validation_Files.xlsx]"&$A$2&"_"&$H$3&"_"&COLUMN(B$2)*100&"k_"&MID(CELL("filename",B3),FIND("]",CELL("filename",B3))+1,255)&"_"&$B$6&"'!H"&ROW(B4)) -> 1 | J8: =INDIRECT("'[CILA2_Validation_Files.xlsx]"&$A$2&"_"&$H$3&"_"&COLUMN(C$2)*100&"k_"&MID(CELL("filename",C3),FIND("]",CELL("filename",C3))+1,255)&"_"&$B$6&"'!H"&ROW(C4)) -> 1 | K8: =INDIRECT("'[CILA2_Validation_Files.xlsx]"&$A$2&"_"&$H$3&"_"&COLUMN(D$2)*100&"k_"&MID(CELL("filename",D3),FIND("]",CELL("filename",D3))+1,255)&"_"&$B$6&"'!H"&ROW(D4)) -> 1 | L8: =INDIRECT("'[CILA2_Validation_Files.xlsx]"&$A$2&"_"&$H$3&"_"&COLUMN(E$2)*100&"k_"&MID(CELL("filename",E3),FIND("]",CELL("filename",E3))+1,255)&"_"&$B$6&"'!H"&ROW(E4)) -> 1 | M8: =INDIRECT("'[CILA2_Validation_Files.xlsx]"&$A$2&"_"&$M$3&"_"&COLUMN(A$2)*100&"k_"&MID(CELL("filename",A3),FIND("]",CELL("filename",A3))+1,255)&"_"&$B$6&"'!H"&ROW(A4)) -> 1 | N8: =INDIRECT("'[CILA2_Validation_Files.xlsx]"&$A$2&"_"&$M$3&"_"&COLUMN(B$2)*100&"k_"&MID(CELL("filename",B3),FIND("]",CELL("filename",B3))+1,255)&"_"&$B$6&"'!H"&ROW(B4)) -> 1 | O8: =INDIRECT("'[CILA2_Validation_Files.xlsx]"&$A$2&"_"&$M$3&"_"&COLUMN(C$2)*100&"k_"&MID(CELL("filename",C3),FIND("]",CELL("filename",C3))+1,255)&"_"&$B$6&"'!H"&ROW(C4)) -> 1 | P8: =INDIRECT("'[CILA2_Validation_Files.xlsx]"&$A$2&"_"&$M$3&"_"&COLUMN(D$2)*100&"k_"&MID(CELL("filename",D3),FIND("]",CELL("filename",D3))+1,255)&"_"&$B$6&"'!H"&ROW(D4)) -> 1 | Q8: =INDIRECT("'[CILA2_Validation_Files.xlsx]"&$A$2&"_"&$M$3&"_"&COLUMN(E$2)*100&"k_"&MID(CELL("filename",E3),FIND("]",CELL("filename",E3))+1,255)&"_"&$B$6&"'!H"&ROW(E4)) -> 1 | R8: =INDIRECT("'[CILA2_Validation_Files.xlsx]"&$A$2&"_"&$R$3&"_"&COLUMN(A$2)*100&"k_"&MID(CELL("filename",A3),FIND("]",CELL("filename",A3))+1,255)&"_"&$B$6&"'!H"&ROW(A4)) -> 1 | S8: =INDIRECT("'[CILA2_Validation_Files.xlsx]"&$A$2&"_"&$R$3&"_"&COLUMN(B$2)*100&"k_"&MID(CELL("filename",B3),FIND("]",CELL("filename",B3))+1,255)&"_"&$B$6&"'!H"&ROW(B4)) -> 1 | T8: =INDIRECT("'[CILA2_Validation_Files.xlsx]"&$A$2&"_"&$R$3&"_"&COLUMN(C$2)*100&"k_"&MID(CELL("filename",C3),FIND("]",CELL("filename",C3))+1,255)&"_"&$B$6&"'!H"&ROW(C4)) -> 1 | U8: =INDIRECT("'[CILA2_Validation_Files.xlsx]"&$A$2&"_"&$R$3&"_"&COLUMN(D$2)*100&"k_"&MID(CELL("filename",D3),FIND("]",CELL("filename",D3))+1,255)&"_"&$B$6&"'!H"&ROW(D4)) -> 1 | V8: =INDIRECT("'[CILA2_Validation_Files.xlsx]"&$A$2&"_"&$R$3&"_"&COLUMN(E$2)*100&"k_"&MID(CELL("filename",E3),FIND("]",CELL("filename",E3))+1,255)&"_"&$B$6&"'!H"&ROW(E4)) -> 1 | W8: =INDIRECT("'[CILA2_Validation_Files.xlsx]"&$A$2&"_"&$W$3&"_"&COLUMN(A$2)*100&"k_"&MID(CELL("filename",A3),FIND("]",CELL("filename",A3))+1,255)&"_"&$B$6&"'!H"&ROW(A4)) -> 1 | X8: =INDIRECT("'[CILA2_Validation_Files.xlsx]"&$A$2&"_"&$W$3&"_"&COLUMN(B$2)*100&"k_"&MID(CELL("filename",B3),FIND("]",CELL("filename",B3))+1,255)&"_"&$B$6&"'!H"&ROW(B4)) -> 1 | Y8: =INDIRECT("'[CILA2_Validation_Files.xlsx]"&$A$2&"_"&$W$3&"_"&COLUMN(C$2)*100&"k_"&MID(CELL("filename",C3),FIND("]",CELL("filename",C3))+1,255)&"_"&$B$6&"'!H"&ROW(C4)) -> 1 | Z8: =INDIRECT("'[CILA2_Validation_Files.xlsx]"&$A$2&"_"&$W$3&"_"&COLUMN(D$2)*100&"k_"&MID(CELL("filename",D3),FIND("]",CELL("filename",D3))+1,255)&"_"&$B$6&"'!H"&ROW(D4)) -> 1 | AA8: =INDIRECT("'[CILA2_Validation_Files.xlsx]"&$A$2&"_"&$W$3&"_"&COLUMN(E$2)*100&"k_"&MID(CELL("filename",E3),FIND("]",CELL("filename",E3))+1,255)&"_"&$B$6&"'!H"&ROW(E4)) -> 1
A9: 4 | C9: =INDIRECT("'[CILA2_Validation_Files.xlsx]"&$A$2&"_"&$C$3&"_"&COLUMN(A$2)*100&"k_"&MID(CELL("filename",A4),FIND("]",CELL("filename",A4))+1,255)&"_"&$B$6&"'!H"&ROW(A5)) -> 1 | D9: =INDIRECT("'[CILA2_Validation_Files.xlsx]"&$A$2&"_"&$C$3&"_"&COLUMN(B$2)*100&"k_"&MID(CELL("filename",B4),FIND("]",CELL("filename",B4))+1,255)&"_"&$B$6&"'!H"&ROW(B5)) -> 1 | E9: =INDIRECT("'[CILA2_Validation_Files.xlsx]"&$A$2&"_"&$C$3&"_"&COLUMN(C$2)*100&"k_"&MID(CELL("filename",C4),FIND("]",CELL("filename",C4))+1,255)&"_"&$B$6&"'!H"&ROW(C5)) -> 1 | F9: =INDIRECT("'[CILA2_Validation_Files.xlsx]"&$A$2&"_"&$C$3&"_"&COLUMN(D$2)*100&"k_"&MID(CELL("filename",D4),FIND("]",CELL("filename",D4))+1,255)&"_"&$B$6&"'!H"&ROW(D5)) -> 1 | G9: =INDIRECT("'[CILA2_Validation_Files.xlsx]"&$A$2&"_"&$C$3&"_"&COLUMN(E$2)*100&"k_"&MID(CELL("filename",E4),FIND("]",CELL("filename",E4))+1,255)&"_"&$B$6&"'!H"&ROW(E5)) -> 1 | H9: =INDIRECT("'[CILA2_Validation_Files.xlsx]"&$A$2&"_"&$H$3&"_"&COLUMN(A$2)*100&"k_"&MID(CELL("filename",A4),FIND("]",CELL("filename",A4))+1,255)&"_"&$B$6&"'!H"&ROW(A5)) -> 1 | I9: =INDIRECT("'[CILA2_Validation_Files.xlsx]"&$A$2&"_"&$H$3&"_"&COLUMN(B$2)*100&"k_"&MID(CELL("filename",B4),FIND("]",CELL("filename",B4))+1,255)&"_"&$B$6&"'!H"&ROW(B5)) -> 1 | J9: =INDIRECT("'[CILA2_Validation_Files.xlsx]"&$A$2&"_"&$H$3&"_"&COLUMN(C$2)*100&"k_"&MID(CELL("filename",C4),FIND("]",CELL("filename",C4))+1,255)&"_"&$B$6&"'!H"&ROW(C5)) -> 1 | K9: =INDIRECT("'[CILA2_Validation_Files.xlsx]"&$A$2&"_"&$H$3&"_"&COLUMN(D$2)*100&"k_"&MID(CELL("filename",D4),FIND("]",CELL("filename",D4))+1,255)&"_"&$B$6&"'!H"&ROW(D5)) -> 1 | L9: =INDIRECT("'[CILA2_Validation_Files.xlsx]"&$A$2&"_"&$H$3&"_"&COLUMN(E$2)*100&"k_"&MID(CELL("filename",E4),FIND("]",CELL("filename",E4))+1,255)&"_"&$B$6&"'!H"&ROW(E5)) -> 1 | M9: =INDIRECT("'[CILA2_Validation_Files.xlsx]"&$A$2&"_"&$M$3&"_"&COLUMN(A$2)*100&"k_"&MID(CELL("filename",A4),FIND("]",CELL("filename",A4))+1,255)&"_"&$B$6&"'!H"&ROW(A5)) -> 1 | N9: =INDIRECT("'[CILA2_Validation_Files.xlsx]"&$A$2&"_"&$M$3&"_"&COLUMN(B$2)*100&"k_"&MID(CELL("filename",B4),FIND("]",CELL("filename",B4))+1,255)&"_"&$B$6&"'!H"&ROW(B5)) -> 1 | O9: =INDIRECT("'[CILA2_Validation_Files.xlsx]"&$A$2&"_"&$M$3&"_"&COLUMN(C$2)*100&"k_"&MID(CELL("filename",C4),FIND("]",CELL("filename",C4))+1,255)&"_"&$B$6&"'!H"&ROW(C5)) -> 1 | P9: =INDIRECT("'[CILA2_Validation_Files.xlsx]"&$A$2&"_"&$M$3&"_"&COLUMN(D$2)*100&"k_"&MID(CELL("filename",D4),FIND("]",CELL("filename",D4))+1,255)&"_"&$B$6&"'!H"&ROW(D5)) -> 1 | Q9: =INDIRECT("'[CILA2_Validation_Files.xlsx]"&$A$2&"_"&$M$3&"_"&COLUMN(E$2)*100&"k_"&MID(CELL("filename",E4),FIND("]",CELL("filename",E4))+1,255)&"_"&$B$6&"'!H"&ROW(E5)) -> 1 | R9: =INDIRECT("'[CILA2_Validation_Files.xlsx]"&$A$2&"_"&$R$3&"_"&COLUMN(A$2)*100&"k_"&MID(CELL("filename",A4),FIND("]",CELL("filename",A4))+1,255)&"_"&$B$6&"'!H"&ROW(A5)) -> 1 | S9: =INDIRECT("'[CILA2_Validation_Files.xlsx]"&$A$2&"_"&$R$3&"_"&COLUMN(B$2)*100&"k_"&MID(CELL("filename",B4),FIND("]",CELL("filename",B4))+1,255)&"_"&$B$6&"'!H"&ROW(B5)) -> 1 | T9: =INDIRECT("'[CILA2_Validation_Files.xlsx]"&$A$2&"_"&$R$3&"_"&COLUMN(C$2)*100&"k_"&MID(CELL("filename",C4),FIND("]",CELL("filename",C4))+1,255)&"_"&$B$6&"'!H"&ROW(C5)) -> 1 | U9: =INDIRECT("'[CILA2_Validation_Files.xlsx]"&$A$2&"_"&$R$3&"_"&COLUMN(D$2)*100&"k_"&MID(CELL("filename",D4),FIND("]",CELL("filename",D4))+1,255)&"_"&$B$6&"'!H"&ROW(D5)) -> 1 | V9: =INDIRECT("'[CILA2_Validation_Files.xlsx]"&$A$2&"_"&$R$3&"_"&COLUMN(E$2)*100&"k_"&MID(CELL("filename",E4),FIND("]",CELL("filename",E4))+1,255)&"_"&$B$6&"'!H"&ROW(E5)) -> 1 | W9: =INDIRECT("'[CILA2_Validation_Files.xlsx]"&$A$2&"_"&$W$3&"_"&COLUMN(A$2)*100&"k_"&MID(CELL("filename",A4),FIND("]",CELL("filename",A4))+1,255)&"_"&$B$6&"'!H"&ROW(A5)) -> 1 | X9: =INDIRECT("'[CILA2_Validation_Files.xlsx]"&$A$2&"_"&$W$3&"_"&COLUMN(B$2)*100&"k_"&MID(CELL("filename",B4),FIND("]",CELL("filename",B4))+1,255)&"_"&$B$6&"'!H"&ROW(B5)) -> 1 | Y9: =INDIRECT("'[CILA2_Validation_Files.xlsx]"&$A$2&"_"&$W$3&"_"&COLUMN(C$2)*100&"k_"&MID(CELL("filename",C4),FIND("]",CELL("filename",C4))+1,255)&"_"&$B$6&"'!H"&ROW(C5)) -> 1 | Z9: =INDIRECT("'[CILA2_Validation_Files.xlsx]"&$A$2&"_"&$W$3&"_"&COLUMN(D$2)*100&"k_"&MID(CELL("filename",D4),FIND("]",CELL("filename",D4))+1,255)&"_"&$B$6&"'!H"&ROW(D5)) -> 1 | AA9: =INDIRECT("'[CILA2_Validation_Files.xlsx]"&$A$2&"_"&$W$3&"_"&COLUMN(E$2)*100&"k_"&MID(CELL("filename",E4),FIND("]",CELL("filename",E4))+1,255)&"_"&$B$6&"'!H"&ROW(E5)) -> 1
A10: 5 | C10: =INDIRECT("'[CILA2_Validation_Files.xlsx]"&$A$2&"_"&$C$3&"_"&COLUMN(A$2)*100&"k_"&MID(CELL("filename",A5),FIND("]",CELL("filename",A5))+1,255)&"_"&$B$6&"'!H"&ROW(A6)) -> 1 | D10: =INDIRECT("'[CILA2_Validation_Files.xlsx]"&$A$2&"_"&$C$3&"_"&COLUMN(B$2)*100&"k_"&MID(CELL("filename",B5),FIND("]",CELL("filename",B5))+1,255)&"_"&$B$6&"'!H"&ROW(B6)) -> 1 | E10: =INDIRECT("'[CILA2_Validation_Files.xlsx]"&$A$2&"_"&$C$3&"_"&COLUMN(C$2)*100&"k_"&MID(CELL("filename",C5),FIND("]",CELL("filename",C5))+1,255)&"_"&$B$6&"'!H"&ROW(C6)) -> 1 | F10: =INDIRECT("'[CILA2_Validation_Files.xlsx]"&$A$2&"_"&$C$3&"_"&COLUMN(D$2)*100&"k_"&MID(CELL("filename",D5),FIND("]",CELL("filename",D5))+1,255)&"_"&$B$6&"'!H"&ROW(D6)) -> 1 | G10: =INDIRECT("'[CILA2_Validation_Files.xlsx]"&$A$2&"_"&$C$3&"_"&COLUMN(E$2)*100&"k_"&MID(CELL("filename",E5),FIND("]",CELL("filename",E5))+1,255)&"_"&$B$6&"'!H"&ROW(E6)) -> 1 | H10: =INDIRECT("'[CILA2_Validation_Files.xlsx]"&$A$2&"_"&$H$3&"_"&COLUMN(A$2)*100&"k_"&MID(CELL("filename",A5),FIND("]",CELL("filename",A5))+1,255)&"_"&$B$6&"'!H"&ROW(A6)) -> 1 | I10: =INDIRECT("'[CILA2_Validation_Files.xlsx]"&$A$2&"_"&$H$3&"_"&COLUMN(B$2)*100&"k_"&MID(CELL("filename",B5),FIND("]",CELL("filename",B5))+1,255)&"_"&$B$6&"'!H"&ROW(B6)) -> 1 | J10: =INDIRECT("'[CILA2_Validation_Files.xlsx]"&$A$2&"_"&$H$3&"_"&COLUMN(C$2)*100&"k_"&MID(CELL("filename",C5),FIND("]",CELL("filename",C5))+1,255)&"_"&$B$6&"'!H"&ROW(C6)) -> 1 | K10: =INDIRECT("'[CILA2_Validation_Files.xlsx]"&$A$2&"_"&$H$3&"_"&COLUMN(D$2)*100&"k_"&MID(CELL("filename",D5),FIND("]",CELL("filename",D5))+1,255)&"_"&$B$6&"'!H"&ROW(D6)) -> 1 | L10: =INDIRECT("'[CILA2_Validation_Files.xlsx]"&$A$2&"_"&$H$3&"_"&COLUMN(E$2)*100&"k_"&MID(CELL("filename",E5),FIND("]",CELL("filename",E5))+1,255)&"_"&$B$6&"'!H"&ROW(E6)) -> 1 | M10: =INDIRECT("'[CILA2_Validation_Files.xlsx]"&$A$2&"_"&$M$3&"_"&COLUMN(A$2)*100&"k_"&MID(CELL("filename",A5),FIND("]",CELL("filename",A5))+1,255)&"_"&$B$6&"'!H"&ROW(A6)) -> 1 | N10: =INDIRECT("'[CILA2_Validation_Files.xlsx]"&$A$2&"_"&$M$3&"_"&COLUMN(B$2)*100&"k_"&MID(CELL("filename",B5),FIND("]",CELL("filename",B5))+1,255)&"_"&$B$6&"'!H"&ROW(B6)) -> 1 | O10: =INDIRECT("'[CILA2_Validation_Files.xlsx]"&$A$2&"_"&$M$3&"_"&COLUMN(C$2)*100&"k_"&MID(CELL("filename",C5),FIND("]",CELL("filename",C5))+1,255)&"_"&$B$6&"'!H"&ROW(C6)) -> 1 | P10: =INDIRECT("'[CILA2_Validation_Files.xlsx]"&$A$2&"_"&$M$3&"_"&COLUMN(D$2)*100&"k_"&MID(CELL("filename",D5),FIND("]",CELL("filename",D5))+1,255)&"_"&$B$6&"'!H"&ROW(D6)) -> 1 | Q10: =INDIRECT("'[CILA2_Validation_Files.xlsx]"&$A$2&"_"&$M$3&"_"&COLUMN(E$2)*100&"k_"&MID(CELL("filename",E5),FIND("]",CELL("filename",E5))+1,255)&"_"&$B$6&"'!H"&ROW(E6)) -> 1 | R10: =INDIRECT("'[CILA2_Validation_Files.xlsx]"&$A$2&"_"&$R$3&"_"&COLUMN(A$2)*100&"k_"&MID(CELL("filename",A5),FIND("]",CELL("filename",A5))+1,255)&"_"&$B$6&"'!H"&ROW(A6)) -> 1 | S10: =INDIRECT("'[CILA2_Validation_Files.xlsx]"&$A$2&"_"&$R$3&"_"&COLUMN(B$2)*100&"k_"&MID(CELL("filename",B5),FIND("]",CELL("filename",B5))+1,255)&"_"&$B$6&"'!H"&ROW(B6)) -> 1 | T10: =INDIRECT("'[CILA2_Validation_Files.xlsx]"&$A$2&"_"&$R$3&"_"&COLUMN(C$2)*100&"k_"&MID(CELL("filename",C5),FIND("]",CELL("filename",C5))+1,255)&"_"&$B$6&"'!H"&ROW(C6)) -> 1 | U10: =INDIRECT("'[CILA2_Validation_Files.xlsx]"&$A$2&"_"&$R$3&"_"&COLUMN(D$2)*100&"k_"&MID(CELL("filename",D5),FIND("]",CELL("filename",D5))+1,255)&"_"&$B$6&"'!H"&ROW(D6)) -> 1 | V10: =INDIRECT("'[CILA2_Validation_Files.xlsx]"&$A$2&"_"&$R$3&"_"&COLUMN(E$2)*100&"k_"&MID(CELL("filename",E5),FIND("]",CELL("filename",E5))+1,255)&"_"&$B$6&"'!H"&ROW(E6)) -> 1 | W10: =INDIRECT("'[CILA2_Validation_Files.xlsx]"&$A$2&"_"&$W$3&"_"&COLUMN(A$2)*100&"k_"&MID(CELL("filename",A5),FIND("]",CELL("filename",A5))+1,255)&"_"&$B$6&"'!H"&ROW(A6)) -> 1 | X10: =INDIRECT("'[CILA2_Validation_Files.xlsx]"&$A$2&"_"&$W$3&"_"&COLUMN(B$2)*100&"k_"&MID(CELL("filename",B5),FIND("]",CELL("filename",B5))+1,255)&"_"&$B$6&"'!H"&ROW(B6)) -> 1 | Y10: =INDIRECT("'[CILA2_Validation_Files.xlsx]"&$A$2&"_"&$W$3&"_"&COLUMN(C$2)*100&"k_"&MID(CELL("filename",C5),FIND("]",CELL("filename",C5))+1,255)&"_"&$B$6&"'!H"&ROW(C6)) -> 1 | Z10: =INDIRECT("'[CILA2_Validation_Files.xlsx]"&$A$2&"_"&$W$3&"_"&COLUMN(D$2)*100&"k_"&MID(CELL("filename",D5),FIND("]",CELL("filename",D5))+1,255)&"_"&$B$6&"'!H"&ROW(D6)) -> 1 | AA10: =INDIRECT("'[CILA2_Validation_Files.xlsx]"&$A$2&"_"&$W$3&"_"&COLUMN(E$2)*100&"k_"&MID(CELL("filename",E5),FIND("]",CELL("filename",E5))+1,255)&"_"&$B$6&"'!H"&ROW(E6)) -> 1
A11: 6 | C11: =INDIRECT("'[CILA2_Validation_Files.xlsx]"&$A$2&"_"&$C$3&"_"&COLUMN(A$2)*100&"k_"&MID(CELL("filename",A6),FIND("]",CELL("filename",A6))+1,255)&"_"&$B$6&"'!H"&ROW(A7)) -> 1 | D11: =INDIRECT("'[CILA2_Validation_Files.xlsx]"&$A$2&"_"&$C$3&"_"&COLUMN(B$2)*100&"k_"&MID(CELL("filename",B6),FIND("]",CELL("filename",B6))+1,255)&"_"&$B$6&"'!H"&ROW(B7)) -> 1 | E11: =INDIRECT("'[CILA2_Validation_Files.xlsx]"&$A$2&"_"&$C$3&"_"&COLUMN(C$2)*100&"k_"&MID(CELL("filename",C6),FIND("]",CELL("filename",C6))+1,255)&"_"&$B$6&"'!H"&ROW(C7)) -> 1 | F11: =INDIRECT("'[CILA2_Validation_Files.xlsx]"&$A$2&"_"&$C$3&"_"&COLUMN(D$2)*100&"k_"&MID(CELL("filename",D6),FIND("]",CELL("filename",D6))+1,255)&"_"&$B$6&"'!H"&ROW(D7)) -> 1 | G11: =INDIRECT("'[CILA2_Validation_Files.xlsx]"&$A$2&"_"&$C$3&"_"&COLUMN(E$2)*100&"k_"&MID(CELL("filename",E6),FIND("]",CELL("filename",E6))+1,255)&"_"&$B$6&"'!H"&ROW(E7)) -> 1 | H11: =INDIRECT("'[CILA2_Validation_Files.xlsx]"&$A$2&"_"&$H$3&"_"&COLUMN(A$2)*100&"k_"&MID(CELL("filename",A6),FIND("]",CELL("filename",A6))+1,255)&"_"&$B$6&"'!H"&ROW(A7)) -> 1 | I11: =INDIRECT("'[CILA2_Validation_Files.xlsx]"&$A$2&"_"&$H$3&"_"&COLUMN(B$2)*100&"k_"&MID(CELL("filename",B6),FIND("]",CELL("filename",B6))+1,255)&"_"&$B$6&"'!H"&ROW(B7)) -> 1 | J11: =INDIRECT("'[CILA2_Validation_Files.xlsx]"&$A$2&"_"&$H$3&"_"&COLUMN(C$2)*100&"k_"&MID(CELL("filename",C6),FIND("]",CELL("filename",C6))+1,255)&"_"&$B$6&"'!H"&ROW(C7)) -> 1 | K11: =INDIRECT("'[CILA2_Validation_Files.xlsx]"&$A$2&"_"&$H$3&"_"&COLUMN(D$2)*100&"k_"&MID(CELL("filename",D6),FIND("]",CELL("filename",D6))+1,255)&"_"&$B$6&"'!H"&ROW(D7)) -> 1 | L11: =INDIRECT("'[CILA2_Validation_Files.xlsx]"&$A$2&"_"&$H$3&"_"&COLUMN(E$2)*100&"k_"&MID(CELL("filename",E6),FIND("]",CELL("filename",E6))+1,255)&"_"&$B$6&"'!H"&ROW(E7)) -> 1 | M11: =INDIRECT("'[CILA2_Validation_Files.xlsx]"&$A$2&"_"&$M$3&"_"&COLUMN(A$2)*100&"k_"&MID(CELL("filename",A6),FIND("]",CELL("filename",A6))+1,255)&"_"&$B$6&"'!H"&ROW(A7)) -> 1 | N11: =INDIRECT("'[CILA2_Validation_Files.xlsx]"&$A$2&"_"&$M$3&"_"&COLUMN(B$2)*100&"k_"&MID(CELL("filename",B6),FIND("]",CELL("filename",B6))+1,255)&"_"&$B$6&"'!H"&ROW(B7)) -> 1 | O11: =INDIRECT("'[CILA2_Validation_Files.xlsx]"&$A$2&"_"&$M$3&"_"&COLUMN(C$2)*100&"k_"&MID(CELL("filename",C6),FIND("]",CELL("filename",C6))+1,255)&"_"&$B$6&"'!H"&ROW(C7)) -> 1 | P11: =INDIRECT("'[CILA2_Validation_Files.xlsx]"&$A$2&"_"&$M$3&"_"&COLUMN(D$2)*100&"k_"&MID(CELL("filename",D6),FIND("]",CELL("filename",D6))+1,255)&"_"&$B$6&"'!H"&ROW(D7)) -> 1 | Q11: =INDIRECT("'[CILA2_Validation_Files.xlsx]"&$A$2&"_"&$M$3&"_"&COLUMN(E$2)*100&"k_"&MID(CELL("filename",E6),FIND("]",CELL("filename",E6))+1,255)&"_"&$B$6&"'!H"&ROW(E7)) -> 1 | R11: =INDIRECT("'[CILA2_Validation_Files.xlsx]"&$A$2&"_"&$R$3&"_"&COLUMN(A$2)*100&"k_"&MID(CELL("filename",A6),FIND("]",CELL("filename",A6))+1,255)&"_"&$B$6&"'!H"&ROW(A7)) -> 1 | S11: =INDIRECT("'[CILA2_Validation_Files.xlsx]"&$A$2&"_"&$R$3&"_"&COLUMN(B$2)*100&"k_"&MID(CELL("filename",B6),FIND("]",CELL("filename",B6))+1,255)&"_"&$B$6&"'!H"&ROW(B7)) -> 1 | T11: =INDIRECT("'[CILA2_Validation_Files.xlsx]"&$A$2&"_"&$R$3&"_"&COLUMN(C$2)*100&"k_"&MID(CELL("filename",C6),FIND("]",CELL("filename",C6))+1,255)&"_"&$B$6&"'!H"&ROW(C7)) -> 1 | U11: =INDIRECT("'[CILA2_Validation_Files.xlsx]"&$A$2&"_"&$R$3&"_"&COLUMN(D$2)*100&"k_"&MID(CELL("filename",D6),FIND("]",CELL("filename",D6))+1,255)&"_"&$B$6&"'!H"&ROW(D7)) -> 1 | V11: =INDIRECT("'[CILA2_Validation_Files.xlsx]"&$A$2&"_"&$R$3&"_"&COLUMN(E$2)*100&"k_"&MID(CELL("filename",E6),FIND("]",CELL("filename",E6))+1,255)&"_"&$B$6&"'!H"&ROW(E7)) -> 1 | W11: =INDIRECT("'[CILA2_Validation_Files.xlsx]"&$A$2&"_"&$W$3&"_"&COLUMN(A$2)*100&"k_"&MID(CELL("filename",A6),FIND("]",CELL("filename",A6))+1,255)&"_"&$B$6&"'!H"&ROW(A7)) -> 1 | X11: =INDIRECT("'[CILA2_Validation_Files.xlsx]"&$A$2&"_"&$W$3&"_"&COLUMN(B$2)*100&"k_"&MID(CELL("filename",B6),FIND("]",CELL("filename",B6))+1,255)&"_"&$B$6&"'!H"&ROW(B7)) -> 1 | Y11: =INDIRECT("'[CILA2_Validation_Files.xlsx]"&$A$2&"_"&$W$3&"_"&COLUMN(C$2)*100&"k_"&MID(CELL("filename",C6),FIND("]",CELL("filename",C6))+1,255)&"_"&$B$6&"'!H"&ROW(C7)) -> 1 | Z11: =INDIRECT("'[CILA2_Validation_Files.xlsx]"&$A$2&"_"&$W$3&"_"&COLUMN(D$2)*100&"k_"&MID(CELL("filename",D6),FIND("]",CELL("filename",D6))+1,255)&"_"&$B$6&"'!H"&ROW(D7)) -> 1 | AA11: =INDIRECT("'[CILA2_Validation_Files.xlsx]"&$A$2&"_"&$W$3&"_"&COLUMN(E$2)*100&"k_"&MID(CELL("filename",E6),FIND("]",CELL("filename",E6))+1,255)&"_"&$B$6&"'!H"&ROW(E7)) -> 1
A12: 7 | B12: one_turn | C12: =INDIRECT("'[CILA2_Validation_Files.xlsx]"&$A$2&"_"&$C$3&"_"&COLUMN(A$2)*100&"k_"&MID(CELL("filename",A1),FIND("]",CELL("filename",A1))+1,255)&"_"&$B$12&"'!H"&ROW(A2)) -> 1 | D12: =INDIRECT("'[CILA2_Validation_Files.xlsx]"&$A$2&"_"&$C$3&"_"&COLUMN(B$2)*100&"k_"&MID(CELL("filename",B1),FIND("]",CELL("filename",B1))+1,255)&"_"&$B$12&"'!H"&ROW(B2)) -> 1 | E12: =INDIRECT("'[CILA2_Validation_Files.xlsx]"&$A$2&"_"&$C$3&"_"&COLUMN(C$2)*100&"k_"&MID(CELL("filename",C1),FIND("]",CELL("filename",C1))+1,255)&"_"&$B$12&"'!H"&ROW(C2)) -> 1 | F12: =INDIRECT("'[CILA2_Validation_Files.xlsx]"&$A$2&"_"&$C$3&"_"&COLUMN(D$2)*100&"k_"&MID(CELL("filename",D1),FIND("]",CELL("filename",D1))+1,255)&"_"&$B$12&"'!H"&ROW(D2)) -> 1 | G12: =INDIRECT("'[CILA2_Validation_Files.xlsx]"&$A$2&"_"&$C$3&"_"&COLUMN(E$2)*100&"k_"&MID(CELL("filename",E1),FIND("]",CELL("filename",E1))+1,255)&"_"&$B$12&"'!H"&ROW(E2)) -> 1 | H12: =INDIRECT("'[CILA2_Validation_Files.xlsx]"&$A$2&"_"&$H$3&"_"&COLUMN(A$2)*100&"k_"&MID(CELL("filename",A1),FIND("]",CELL("filename",A1))+1,255)&"_"&$B$12&"'!H"&ROW(A2)) -> 0 | I12: =INDIRECT("'[CILA2_Validation_Files.xlsx]"&$A$2&"_"&$H$3&"_"&COLUMN(B$2)*100&"k_"&MID(CELL("filename",B1),FIND("]",CELL("filename",B1))+1,255)&"_"&$B$12&"'!H"&ROW(B2)) -> 0 | J12: =INDIRECT("'[CILA2_Validation_Files.xlsx]"&$A$2&"_"&$H$3&"_"&COLUMN(C$2)*100&"k_"&MID(CELL("filename",C1),FIND("]",CELL("filename",C1))+1,255)&"_"&$B$12&"'!H"&ROW(C2)) -> 1 | K12: =INDIRECT("'[CILA2_Validation_Files.xlsx]"&$A$2&"_"&$H$3&"_"&COLUMN(D$2)*100&"k_"&MID(CELL("filename",D1),FIND("]",CELL("filename",D1))+1,255)&"_"&$B$12&"'!H"&ROW(D2)) -> 1 | L12: =INDIRECT("'[CILA2_Validation_Files.xlsx]"&$A$2&"_"&$H$3&"_"&COLUMN(E$2)*100&"k_"&MID(CELL("filename",E1),FIND("]",CELL("filename",E1))+1,255)&"_"&$B$12&"'!H"&ROW(E2)) -> 1 | M12: =INDIRECT("'[CILA2_Validation_Files.xlsx]"&$A$2&"_"&$M$3&"_"&COLUMN(A$2)*100&"k_"&MID(CELL("filename",A1),FIND("]",CELL("filename",A1))+1,255)&"_"&$B$12&"'!H"&ROW(A2)) -> 1 | N12: =INDIRECT("'[CILA2_Validation_Files.xlsx]"&$A$2&"_"&$M$3&"_"&COLUMN(B$2)*100&"k_"&MID(CELL("filename",B1),FIND("]",CELL("filename",B1))+1,255)&"_"&$B$12&"'!H"&ROW(B2)) -> 1 | O12: =INDIRECT("'[CILA2_Validation_Files.xlsx]"&$A$2&"_"&$M$3&"_"&COLUMN(C$2)*100&"k_"&MID(CELL("filename",C1),FIND("]",CELL("filename",C1))+1,255)&"_"&$B$12&"'!H"&ROW(C2)) -> 1 | P12: =INDIRECT("'[CILA2_Validation_Files.xlsx]"&$A$2&"_"&$M$3&"_"&COLUMN(D$2)*100&"k_"&MID(CELL("filename",D1),FIND("]",CELL("filename",D1))+1,255)&"_"&$B$12&"'!H"&ROW(D2)) -> 1 | Q12: =INDIRECT("'[CILA2_Validation_Files.xlsx]"&$A$2&"_"&$M$3&"_"&COLUMN(E$2)*100&"k_"&MID(CELL("filename",E1),FIND("]",CELL("filename",E1))+1,255)&"_"&$B$12&"'!H"&ROW(E2)) -> 0 | R12: =INDIRECT("'[CILA2_Validation_Files.xlsx]"&$A$2&"_"&$R$3&"_"&COLUMN(A$2)*100&"k_"&MID(CELL("filename",A1),FIND("]",CELL("filename",A1))+1,255)&"_"&$B$12&"'!H"&ROW(A2)) -> 1 | S12: =INDIRECT("'[CILA2_Validation_Files.xlsx]"&$A$2&"_"&$R$3&"_"&COLUMN(B$2)*100&"k_"&MID(CELL("filename",B1),FIND("]",CELL("filename",B1))+1,255)&"_"&$B$12&"'!H"&ROW(B2)) -> 1 | T12: =INDIRECT("'[CILA2_Validation_Files.xlsx]"&$A$2&"_"&$R$3&"_"&COLUMN(C$2)*100&"k_"&MID(CELL("filename",C1),FIND("]",CELL("filename",C1))+1,255)&"_"&$B$12&"'!H"&ROW(C2)) -> 1 | U12: =INDIRECT("'[CILA2_Validation_Files.xlsx]"&$A$2&"_"&$R$3&"_"&COLUMN(D$2)*100&"k_"&MID(CELL("filename",D1),FIND("]",CELL("filename",D1))+1,255)&"_"&$B$12&"'!H"&ROW(D2)) -> 1 | V12: =INDIRECT("'[CILA2_Validation_Files.xlsx]"&$A$2&"_"&$R$3&"_"&COLUMN(E$2)*100&"k_"&MID(CELL("filename",E1),FIND("]",CELL("filename",E1))+1,255)&"_"&$B$12&"'!H"&ROW(E2)) -> 1 | W12: =INDIRECT("'[CILA2_Validation_Files.xlsx]"&$A$2&"_"&$W$3&"_"&COLUMN(A$2)*100&"k_"&MID(CELL("filename",A1),FIND("]",CELL("filename",A1))+1,255)&"_"&$B$12&"'!H"&ROW(A2)) -> 1 | X12: =INDIRECT("'[CILA2_Validation_Files.xlsx]"&$A$2&"_"&$W$3&"_"&COLUMN(B$2)*100&"k_"&MID(CELL("filename",B1),FIND("]",CELL("filename",B1))+1,255)&"_"&$B$12&"'!H"&ROW(B2)) -> 1 | Y12: =INDIRECT("'[CILA2_Validation_Files.xlsx]"&$A$2&"_"&$W$3&"_"&COLUMN(C$2)*100&"k_"&MID(CELL("filename",C1),FIND("]",CELL("filename",C1))+1,255)&"_"&$B$12&"'!H"&ROW(C2)) -> 1 | Z12: =INDIRECT("'[CILA2_Validation_Files.xlsx]"&$A$2&"_"&$W$3&"_"&COLUMN(D$2)*100&"k_"&MID(CELL("filename",D1),FIND("]",CELL("filename",D1))+1,255)&"_"&$B$12&"'!H"&ROW(D2)) -> 0 | AA12: =INDIRECT("'[CILA2_Validation_Files.xlsx]"&$A$2&"_"&$W$3&"_"&COLUMN(E$2)*100&"k_"&MID(CELL("filename",E1),FIND("]",CELL("filename",E1))+1,255)&"_"&$B$12&"'!H"&ROW(E2)) -> 1 | AB12: =AVERAGE(C12:AA17) -> 0.82666667
A13: 8 | C13: =INDIRECT("'[CILA2_Validation_Files.xlsx]"&$A$2&"_"&$C$3&"_"&COLUMN(A$2)*100&"k_"&MID(CELL("filename",A2),FIND("]",CELL("filename",A2))+1,255)&"_"&$B$12&"'!H"&ROW(A3)) -> 1 | D13: =INDIRECT("'[CILA2_Validation_Files.xlsx]"&$A$2&"_"&$C$3&"_"&COLUMN(B$2)*100&"k_"&MID(CELL("filename",B2),FIND("]",CELL("filename",B2))+1,255)&"_"&$B$12&"'!H"&ROW(B3)) -> 1 | E13: =INDIRECT("'[CILA2_Validation_Files.xlsx]"&$A$2&"_"&$C$3&"_"&COLUMN(C$2)*100&"k_"&MID(CELL("filename",C2),FIND("]",CELL("filename",C2))+1,255)&"_"&$B$12&"'!H"&ROW(C3)) -> 1 | F13: =INDIRECT("'[CILA2_Validation_Files.xlsx]"&$A$2&"_"&$C$3&"_"&COLUMN(D$2)*100&"k_"&MID(CELL("filename",D2),FIND("]",CELL("filename",D2))+1,255)&"_"&$B$12&"'!H"&ROW(D3)) -> 1 | G13: =INDIRECT("'[CILA2_Validation_Files.xlsx]"&$A$2&"_"&$C$3&"_"&COLUMN(E$2)*100&"k_"&MID(CELL("filename",E2),FIND("]",CELL("filename",E2))+1,255)&"_"&$B$12&"'!H"&ROW(E3)) -> 1 | H13: =INDIRECT("'[CILA2_Validation_Files.xlsx]"&$A$2&"_"&$H$3&"_"&COLUMN(A$2)*100&"k_"&MID(CELL("filename",A2),FIND("]",CELL("filename",A2))+1,255)&"_"&$B$12&"'!H"&ROW(A3)) -> 0 | I13: =INDIRECT("'[CILA2_Validation_Files.xlsx]"&$A$2&"_"&$H$3&"_"&COLUMN(B$2)*100&"k_"&MID(CELL("filename",B2),FIND("]",CELL("filename",B2))+1,255)&"_"&$B$12&"'!H"&ROW(B3)) -> 1 | J13: =INDIRECT("'[CILA2_Validation_Files.xlsx]"&$A$2&"_"&$H$3&"_"&COLUMN(C$2)*100&"k_"&MID(CELL("filename",C2),FIND("]",CELL("filename",C2))+1,255)&"_"&$B$12&"'!H"&ROW(C3)) -> 1 | K13: =INDIRECT("'[CILA2_Validation_Files.xlsx]"&$A$2&"_"&$H$3&"_"&COLUMN(D$2)*100&"k_"&MID(CELL("filename",D2),FIND("]",CELL("filename",D2))+1,255)&"_"&$B$12&"'!H"&ROW(D3)) -> 1 | L13: =INDIRECT("'[CILA2_Validation_Files.xlsx]"&$A$2&"_"&$H$3&"_"&COLUMN(E$2)*100&"k_"&MID(CELL("filename",E2),FIND("]",CELL("filename",E2))+1,255)&"_"&$B$12&"'!H"&ROW(E3)) -> 1 | M13: =INDIRECT("'[CILA2_Validation_Files.xlsx]"&$A$2&"_"&$M$3&"_"&COLUMN(A$2)*100&"k_"&MID(CELL("filename",A2),FIND("]",CELL("filename",A2))+1,255)&"_"&$B$12&"'!H"&ROW(A3)) -> 1 | N13: =INDIRECT("'[CILA2_Validation_Files.xlsx]"&$A$2&"_"&$M$3&"_"&COLUMN(B$2)*100&"k_"&MID(CELL("filename",B2),FIND("]",CELL("filename",B2))+1,255)&"_"&$B$12&"'!H"&ROW(B3)) -> 1 | O13: =INDIRECT("'[CILA2_Validation_Files.xlsx]"&$A$2&"_"&$M$3&"_"&COLUMN(C$2)*100&"k_"&MID(CELL("filename",C2),FIND("]",CELL("filename",C2))+1,255)&"_"&$B$12&"'!H"&ROW(C3)) -> 1 | P13: =INDIRECT("'[CILA2_Validation_Files.xlsx]"&$A$2&"_"&$M$3&"_"&COLUMN(D$2)*100&"k_"&MID(CELL("filename",D2),FIND("]",CELL("filename",D2))+1,255)&"_"&$B$12&"'!H"&ROW(D3)) -> 1 | Q13: =INDIRECT("'[CILA2_Validation_Files.xlsx]"&$A$2&"_"&$M$3&"_"&COLUMN(E$2)*100&"k_"&MID(CELL("filename",E2),FIND("]",CELL("filename",E2))+1,255)&"_"&$B$12&"'!H"&ROW(E3)) -> 1 | R13: =INDIRECT("'[CILA2_Validation_Files.xlsx]"&$A$2&"_"&$R$3&"_"&COLUMN(A$2)*100&"k_"&MID(CELL("filename",A2),FIND("]",CELL("filename",A2))+1,255)&"_"&$B$12&"'!H"&ROW(A3)) -> 1 | S13: =INDIRECT("'[CILA2_Validation_Files.xlsx]"&$A$2&"_"&$R$3&"_"&COLUMN(B$2)*100&"k_"&MID(CELL("filename",B2),FIND("]",CELL("filename",B2))+1,255)&"_"&$B$12&"'!H"&ROW(B3)) -> 1 | T13: =INDIRECT("'[CILA2_Validation_Files.xlsx]"&$A$2&"_"&$R$3&"_"&COLUMN(C$2)*100&"k_"&MID(CELL("filename",C2),FIND("]",CELL("filename",C2))+1,255)&"_"&$B$12&"'!H"&ROW(C3)) -> 0 | U13: =INDIRECT("'[CILA2_Validation_Files.xlsx]"&$A$2&"_"&$R$3&"_"&COLUMN(D$2)*100&"k_"&MID(CELL("filename",D2),FIND("]",CELL("filename",D2))+1,255)&"_"&$B$12&"'!H"&ROW(D3)) -> 0 | V13: =INDIRECT("'[CILA2_Validation_Files.xlsx]"&$A$2&"_"&$R$3&"_"&COLUMN(E$2)*100&"k_"&MID(CELL("filename",E2),FIND("]",CELL("filename",E2))+1,255)&"_"&$B$12&"'!H"&ROW(E3)) -> 1 | W13: =INDIRECT("'[CILA2_Validation_Files.xlsx]"&$A$2&"_"&$W$3&"_"&COLUMN(A$2)*100&"k_"&MID(CELL("filename",A2),FIND("]",CELL("filename",A2))+1,255)&"_"&$B$12&"'!H"&ROW(A3)) -> 1 | X13: =INDIRECT("'[CILA2_Validation_Files.xlsx]"&$A$2&"_"&$W$3&"_"&COLUMN(B$2)*100&"k_"&MID(CELL("filename",B2),FIND("]",CELL("filename",B2))+1,255)&"_"&$B$12&"'!H"&ROW(B3)) -> 1 | Y13: =INDIRECT("'[CILA2_Validation_Files.xlsx]"&$A$2&"_"&$W$3&"_"&COLUMN(C$2)*100&"k_"&MID(CELL("filename",C2),FIND("]",CELL("filename",C2))+1,255)&"_"&$B$12&"'!H"&ROW(C3)) -> 0 | Z13: =INDIRECT("'[CILA2_Validation_Files.xlsx]"&$A$2&"_"&$W$3&"_"&COLUMN(D$2)*100&"k_"&MID(CELL("filename",D2),FIND("]",CELL("filename",D2))+1,255)&"_"&$B$12&"'!H"&ROW(D3)) -> 1 | AA13: =INDIRECT("'[CILA2_Validation_Files.xlsx]"&$A$2&"_"&$W$3&"_"&COLUMN(E$2)*100&"k_"&MID(CELL("filename",E2),FIND("]",CELL("filename",E2))+1,255)&"_"&$B$12&"'!H"&ROW(E3)) -> 0
A14: 9 | C14: =INDIRECT("'[CILA2_Validation_Files.xlsx]"&$A$2&"_"&$C$3&"_"&COLUMN(A$2)*100&"k_"&MID(CELL("filename",A3),FIND("]",CELL("filename",A3))+1,255)&"_"&$B$12&"'!H"&ROW(A4)) -> 1 | D14: =INDIRECT("'[CILA2_Validation_Files.xlsx]"&$A$2&"_"&$C$3&"_"&COLUMN(B$2)*100&"k_"&MID(CELL("filename",B3),FIND("]",CELL("filename",B3))+1,255)&"_"&$B$12&"'!H"&ROW(B4)) -> 1 | E14: =INDIRECT("'[CILA2_Validation_Files.xlsx]"&$A$2&"_"&$C$3&"_"&COLUMN(C$2)*100&"k_"&MID(CELL("filename",C3),FIND("]",CELL("filename",C3))+1,255)&"_"&$B$12&"'!H"&ROW(C4)) -> 1 | F14: =INDIRECT("'[CILA2_Validation_Files.xlsx]"&$A$2&"_"&$C$3&"_"&COLUMN(D$2)*100&"k_"&MID(CELL("filename",D3),FIND("]",CELL("filename",D3))+1,255)&"_"&$B$12&"'!H"&ROW(D4)) -> 1 | G14: =INDIRECT("'[CILA2_Validation_Files.xlsx]"&$A$2&"_"&$C$3&"_"&COLUMN(E$2)*100&"k_"&MID(CELL("filename",E3),FIND("]",CELL("filename",E3))+1,255)&"_"&$B$12&"'!H"&ROW(E4)) -> 1 | H14: =INDIRECT("'[CILA2_Validation_Files.xlsx]"&$A$2&"_"&$H$3&"_"&COLUMN(A$2)*100&"k_"&MID(CELL("filename",A3),FIND("]",CELL("filename",A3))+1,255)&"_"&$B$12&"'!H"&ROW(A4)) -> 1 | I14: =INDIRECT("'[CILA2_Validation_Files.xlsx]"&$A$2&"_"&$H$3&"_"&COLUMN(B$2)*100&"k_"&MID(CELL("filename",B3),FIND("]",CELL("filename",B3))+1,255)&"_"&$B$12&"'!H"&ROW(B4)) -> 1 | J14: =INDIRECT("'[CILA2_Validation_Files.xlsx]"&$A$2&"_"&$H$3&"_"&COLUMN(C$2)*100&"k_"&MID(CELL("filename",C3),FIND("]",CELL("filename",C3))+1,255)&"_"&$B$12&"'!H"&ROW(C4)) -> 1 | K14: =INDIRECT("'[CILA2_Validation_Files.xlsx]"&$A$2&"_"&$H$3&"_"&COLUMN(D$2)*100&"k_"&MID(CELL("filename",D3),FIND("]",CELL("filename",D3))+1,255)&"_"&$B$12&"'!H"&ROW(D4)) -> 0 | L14: =INDIRECT("'[CILA2_Validation_Files.xlsx]"&$A$2&"_"&$H$3&"_"&COLUMN(E$2)*100&"k_"&MID(CELL("filename",E3),FIND("]",CELL("filename",E3))+1,255)&"_"&$B$12&"'!H"&ROW(E4)) -> 1 | M14: =INDIRECT("'[CILA2_Validation_Files.xlsx]"&$A$2&"_"&$M$3&"_"&COLUMN(A$2)*100&"k_"&MID(CELL("filename",A3),FIND("]",CELL("filename",A3))+1,255)&"_"&$B$12&"'!H"&ROW(A4)) -> 1 | N14: =INDIRECT("'[CILA2_Validation_Files.xlsx]"&$A$2&"_"&$M$3&"_"&COLUMN(B$2)*100&"k_"&MID(CELL("filename",B3),FIND("]",CELL("filename",B3))+1,255)&"_"&$B$12&"'!H"&ROW(B4)) -> 1 | O14: =INDIRECT("'[CILA2_Validation_Files.xlsx]"&$A$2&"_"&$M$3&"_"&COLUMN(C$2)*100&"k_"&MID(CELL("filename",C3),FIND("]",CELL("filename",C3))+1,255)&"_"&$B$12&"'!H"&ROW(C4)) -> 1 | P14: =INDIRECT("'[CILA2_Validation_Files.xlsx]"&$A$2&"_"&$M$3&"_"&COLUMN(D$2)*100&"k_"&MID(CELL("filename",D3),FIND("]",CELL("filename",D3))+1,255)&"_"&$B$12&"'!H"&ROW(D4)) -> 1 | Q14: =INDIRECT("'[CILA2_Validation_Files.xlsx]"&$A$2&"_"&$M$3&"_"&COLUMN(E$2)*100&"k_"&MID(CELL("filename",E3),FIND("]",CELL("filename",E3))+1,255)&"_"&$B$12&"'!H"&ROW(E4)) -> 1 | R14: =INDIRECT("'[CILA2_Validation_Files.xlsx]"&$A$2&"_"&$R$3&"_"&COLUMN(A$2)*100&"k_"&MID(CELL("filename",A3),FIND("]",CELL("filename",A3))+1,255)&"_"&$B$12&"'!H"&ROW(A4)) -> 0 | S14: =INDIRECT("'[CILA2_Validation_Files.xlsx]"&$A$2&"_"&$R$3&"_"&COLUMN(B$2)*100&"k_"&MID(CELL("filename",B3),FIND("]",CELL("filename",B3))+1,255)&"_"&$B$12&"'!H"&ROW(B4)) -> 1 | T14: =INDIRECT("'[CILA2_Validation_Files.xlsx]"&$A$2&"_"&$R$3&"_"&COLUMN(C$2)*100&"k_"&MID(CELL("filename",C3),FIND("]",CELL("filename",C3))+1,255)&"_"&$B$12&"'!H"&ROW(C4)) -> 1 | U14: =INDIRECT("'[CILA2_Validation_Files.xlsx]"&$A$2&"_"&$R$3&"_"&COLUMN(D$2)*100&"k_"&MID(CELL("filename",D3),FIND("]",CELL("filename",D3))+1,255)&"_"&$B$12&"'!H"&ROW(D4)) -> 1 | V14: =INDIRECT("'[CILA2_Validation_Files.xlsx]"&$A$2&"_"&$R$3&"_"&COLUMN(E$2)*100&"k_"&MID(CELL("filename",E3),FIND("]",CELL("filename",E3))+1,255)&"_"&$B$12&"'!H"&ROW(E4)) -> 1 | W14: =INDIRECT("'[CILA2_Validation_Files.xlsx]"&$A$2&"_"&$W$3&"_"&COLUMN(A$2)*100&"k_"&MID(CELL("filename",A3),FIND("]",CELL("filename",A3))+1,255)&"_"&$B$12&"'!H"&ROW(A4)) -> 0 | X14: =INDIRECT("'[CILA2_Validation_Files.xlsx]"&$A$2&"_"&$W$3&"_"&COLUMN(B$2)*100&"k_"&MID(CELL("filename",B3),FIND("]",CELL("filename",B3))+1,255)&"_"&$B$12&"'!H"&ROW(B4)) -> 1 | Y14: =INDIRECT("'[CILA2_Validation_Files.xlsx]"&$A$2&"_"&$W$3&"_"&COLUMN(C$2)*100&"k_"&MID(CELL("filename",C3),FIND("]",CELL("filename",C3))+1,255)&"_"&$B$12&"'!H"&ROW(C4)) -> 0 | Z14: =INDIRECT("'[CILA2_Validation_Files.xlsx]"&$A$2&"_"&$W$3&"_"&COLUMN(D$2)*100&"k_"&MID(CELL("filename",D3),FIND("]",CELL("filename",D3))+1,255)&"_"&$B$12&"'!H"&ROW(D4)) -> 1 | AA14: =INDIRECT("'[CILA2_Validation_Files.xlsx]"&$A$2&"_"&$W$3&"_"&COLUMN(E$2)*100&"k_"&MID(CELL("filename",E3),FIND("]",CELL("filename",E3))+1,255)&"_"&$B$12&"'!H"&ROW(E4)) -> 1
A15: 10 | C15: =INDIRECT("'[CILA2_Validation_Files.xlsx]"&$A$2&"_"&$C$3&"_"&COLUMN(A$2)*100&"k_"&MID(CELL("filename",A4),FIND("]",CELL("filename",A4))+1,255)&"_"&$B$12&"'!H"&ROW(A5)) -> 0 | D15: =INDIRECT("'[CILA2_Validation_Files.xlsx]"&$A$2&"_"&$C$3&"_"&COLUMN(B$2)*100&"k_"&MID(CELL("filename",B4),FIND("]",CELL("filename",B4))+1,255)&"_"&$B$12&"'!H"&ROW(B5)) -> 0 | E15: =INDIRECT("'[CILA2_Validation_Files.xlsx]"&$A$2&"_"&$C$3&"_"&COLUMN(C$2)*100&"k_"&MID(CELL("filename",C4),FIND("]",CELL("filename",C4))+1,255)&"_"&$B$12&"'!H"&ROW(C5)) -> 1 | F15: =INDIRECT("'[CILA2_Validation_Files.xlsx]"&$A$2&"_"&$C$3&"_"&COLUMN(D$2)*100&"k_"&MID(CELL("filename",D4),FIND("]",CELL("filename",D4))+1,255)&"_"&$B$12&"'!H"&ROW(D5)) -> 1 | G15: =INDIRECT("'[CILA2_Validation_Files.xlsx]"&$A$2&"_"&$C$3&"_"&COLUMN(E$2)*100&"k_"&MID(CELL("filename",E4),FIND("]",CELL("filename",E4))+1,255)&"_"&$B$12&"'!H"&ROW(E5)) -> 0 | H15: =INDIRECT("'[CILA2_Validation_Files.xlsx]"&$A$2&"_"&$H$3&"_"&COLUMN(A$2)*100&"k_"&MID(CELL("filename",A4),FIND("]",CELL("filename",A4))+1,255)&"_"&$B$12&"'!H"&ROW(A5)) -> 1 | I15: =INDIRECT("'[CILA2_Validation_Files.xlsx]"&$A$2&"_"&$H$3&"_"&COLUMN(B$2)*100&"k_"&MID(CELL("filename",B4),FIND("]",CELL("filename",B4))+1,255)&"_"&$B$12&"'!H"&ROW(B5)) -> 1 | J15: =INDIRECT("'[CILA2_Validation_Files.xlsx]"&$A$2&"_"&$H$3&"_"&COLUMN(C$2)*100&"k_"&MID(CELL("filename",C4),FIND("]",CELL("filename",C4))+1,255)&"_"&$B$12&"'!H"&ROW(C5)) -> 1 | K15: =INDIRECT("'[CILA2_Validation_Files.xlsx]"&$A$2&"_"&$H$3&"_"&COLUMN(D$2)*100&"k_"&MID(CELL("filename",D4),FIND("]",CELL("filename",D4))+1,255)&"_"&$B$12&"'!H"&ROW(D5)) -> 1 | L15: =INDIRECT("'[CILA2_Validation_Files.xlsx]"&$A$2&"_"&$H$3&"_"&COLUMN(E$2)*100&"k_"&MID(CELL("filename",E4),FIND("]",CELL("filename",E4))+1,255)&"_"&$B$12&"'!H"&ROW(E5)) -> 1 | M15: =INDIRECT("'[CILA2_Validation_Files.xlsx]"&$A$2&"_"&$M$3&"_"&COLUMN(A$2)*100&"k_"&MID(CELL("filename",A4),FIND("]",CELL("filename",A4))+1,255)&"_"&$B$12&"'!H"&ROW(A5)) -> 1 | N15: =INDIRECT("'[CILA2_Validation_Files.xlsx]"&$A$2&"_"&$M$3&"_"&COLUMN(B$2)*100&"k_"&MID(CELL("filename",B4),FIND("]",CELL("filename",B4))+1,255)&"_"&$B$12&"'!H"&ROW(B5)) -> 1 | O15: =INDIRECT("'[CILA2_Validation_Files.xlsx]"&$A$2&"_"&$M$3&"_"&COLUMN(C$2)*100&"k_"&MID(CELL("filename",C4),FIND("]",CELL("filename",C4))+1,255)&"_"&$B$12&"'!H"&ROW(C5)) -> 1 | P15: =INDIRECT("'[CILA2_Validation_Files.xlsx]"&$A$2&"_"&$M$3&"_"&COLUMN(D$2)*100&"k_"&MID(CELL("filename",D4),FIND("]",CELL("filename",D4))+1,255)&"_"&$B$12&"'!H"&ROW(D5)) -> 1 | Q15: =INDIRECT("'[CILA2_Validation_Files.xlsx]"&$A$2&"_"&$M$3&"_"&COLUMN(E$2)*100&"k_"&MID(CELL("filename",E4),FIND("]",CELL("filename",E4))+1,255)&"_"&$B$12&"'!H"&ROW(E5)) -> 1 | R15: =INDIRECT("'[CILA2_Validation_Files.xlsx]"&$A$2&"_"&$R$3&"_"&COLUMN(A$2)*100&"k_"&MID(CELL("filename",A4),FIND("]",CELL("filename",A4))+1,255)&"_"&$B$12&"'!H"&ROW(A5)) -> 1 | S15: =INDIRECT("'[CILA2_Validation_Files.xlsx]"&$A$2&"_"&$R$3&"_"&COLUMN(B$2)*100&"k_"&MID(CELL("filename",B4),FIND("]",CELL("filename",B4))+1,255)&"_"&$B$12&"'!H"&ROW(B5)) -> 1 | T15: =INDIRECT("'[CILA2_Validation_Files.xlsx]"&$A$2&"_"&$R$3&"_"&COLUMN(C$2)*100&"k_"&MID(CELL("filename",C4),FIND("]",CELL("filename",C4))+1,255)&"_"&$B$12&"'!H"&ROW(C5)) -> 1 | U15: =INDIRECT("'[CILA2_Validation_Files.xlsx]"&$A$2&"_"&$R$3&"_"&COLUMN(D$2)*100&"k_"&MID(CELL("filename",D4),FIND("]",CELL("filename",D4))+1,255)&"_"&$B$12&"'!H"&ROW(D5)) -> 1 | V15: =INDIRECT("'[CILA2_Validation_Files.xlsx]"&$A$2&"_"&$R$3&"_"&COLUMN(E$2)*100&"k_"&MID(CELL("filename",E4),FIND("]",CELL("filename",E4))+1,255)&"_"&$B$12&"'!H"&ROW(E5)) -> 1 | W15: =INDIRECT("'[CILA2_Validation_Files.xlsx]"&$A$2&"_"&$W$3&"_"&COLUMN(A$2)*100&"k_"&MID(CELL("filename",A4),FIND("]",CELL("filename",A4))+1,255)&"_"&$B$12&"'!H"&ROW(A5)) -> 1 | X15: =INDIRECT("'[CILA2_Validation_Files.xlsx]"&$A$2&"_"&$W$3&"_"&COLUMN(B$2)*100&"k_"&MID(CELL("filename",B4),FIND("]",CELL("filename",B4))+1,255)&"_"&$B$12&"'!H"&ROW(B5)) -> 1 | Y15: =INDIRECT("'[CILA2_Validation_Files.xlsx]"&$A$2&"_"&$W$3&"_"&COLUMN(C$2)*100&"k_"&MID(CELL("filename",C4),FIND("]",CELL("filename",C4))+1,255)&"_"&$B$12&"'!H"&ROW(C5)) -> 1 | Z15: =INDIRECT("'[CILA2_Validation_Files.xlsx]"&$A$2&"_"&$W$3&"_"&COLUMN(D$2)*100&"k_"&MID(CELL("filename",D4),FIND("]",CELL("filename",D4))+1,255)&"_"&$B$12&"'!H"&ROW(D5)) -> 1 | AA15: =INDIRECT("'[CILA2_Validation_Files.xlsx]"&$A$2&"_"&$W$3&"_"&COLUMN(E$2)*100&"k_"&MID(CELL("filename",E4),FIND("]",CELL("filename",E4))+1,255)&"_"&$B$12&"'!H"&ROW(E5)) -> 0
A16: 11 | C16: =INDIRECT("'[CILA2_Validation_Files.xlsx]"&$A$2&"_"&$C$3&"_"&COLUMN(A$2)*100&"k_"&MID(CELL("filename",A5),FIND("]",CELL("filename",A5))+1,255)&"_"&$B$12&"'!H"&ROW(A6)) -> 0 | D16: =INDIRECT("'[CILA2_Validation_Files.xlsx]"&$A$2&"_"&$C$3&"_"&COLUMN(B$2)*100&"k_"&MID(CELL("filename",B5),FIND("]",CELL("filename",B5))+1,255)&"_"&$B$12&"'!H"&ROW(B6)) -> 1 | E16: =INDIRECT("'[CILA2_Validation_Files.xlsx]"&$A$2&"_"&$C$3&"_"&COLUMN(C$2)*100&"k_"&MID(CELL("filename",C5),FIND("]",CELL("filename",C5))+1,255)&"_"&$B$12&"'!H"&ROW(C6)) -> 1 | F16: =INDIRECT("'[CILA2_Validation_Files.xlsx]"&$A$2&"_"&$C$3&"_"&COLUMN(D$2)*100&"k_"&MID(CELL("filename",D5),FIND("]",CELL("filename",D5))+1,255)&"_"&$B$12&"'!H"&ROW(D6)) -> 1 | G16: =INDIRECT("'[CILA2_Validation_Files.xlsx]"&$A$2&"_"&$C$3&"_"&COLUMN(E$2)*100&"k_"&MID(CELL("filename",E5),FIND("]",CELL("filename",E5))+1,255)&"_"&$B$12&"'!H"&ROW(E6)) -> 1 | H16: =INDIRECT("'[CILA2_Validation_Files.xlsx]"&$A$2&"_"&$H$3&"_"&COLUMN(A$2)*100&"k_"&MID(CELL("filename",A5),FIND("]",CELL("filename",A5))+1,255)&"_"&$B$12&"'!H"&ROW(A6)) -> 0 | I16: =INDIRECT("'[CILA2_Validation_Files.xlsx]"&$A$2&"_"&$H$3&"_"&COLUMN(B$2)*100&"k_"&MID(CELL("filename",B5),FIND("]",CELL("filename",B5))+1,255)&"_"&$B$12&"'!H"&ROW(B6)) -> 1 | J16: =INDIRECT("'[CILA2_Validation_Files.xlsx]"&$A$2&"_"&$H$3&"_"&COLUMN(C$2)*100&"k_"&MID(CELL("filename",C5),FIND("]",CELL("filename",C5))+1,255)&"_"&$B$12&"'!H"&ROW(C6)) -> 1 | K16: =INDIRECT("'[CILA2_Validation_Files.xlsx]"&$A$2&"_"&$H$3&"_"&COLUMN(D$2)*100&"k_"&MID(CELL("filename",D5),FIND("]",CELL("filename",D5))+1,255)&"_"&$B$12&"'!H"&ROW(D6)) -> 1 | L16: =INDIRECT("'[CILA2_Validation_Files.xlsx]"&$A$2&"_"&$H$3&"_"&COLUMN(E$2)*100&"k_"&MID(CELL("filename",E5),FIND("]",CELL("filename",E5))+1,255)&"_"&$B$12&"'!H"&ROW(E6)) -> 1 | M16: =INDIRECT("'[CILA2_Validation_Files.xlsx]"&$A$2&"_"&$M$3&"_"&COLUMN(A$2)*100&"k_"&MID(CELL("filename",A5),FIND("]",CELL("filename",A5))+1,255)&"_"&$B$12&"'!H"&ROW(A6)) -> 0 | N16: =INDIRECT("'[CILA2_Validation_Files.xlsx]"&$A$2&"_"&$M$3&"_"&COLUMN(B$2)*100&"k_"&MID(CELL("filename",B5),FIND("]",CELL("filename",B5))+1,255)&"_"&$B$12&"'!H"&ROW(B6)) -> 1 | O16: =INDIRECT("'[CILA2_Validation_Files.xlsx]"&$A$2&"_"&$M$3&"_"&COLUMN(C$2)*100&"k_"&MID(CELL("filename",C5),FIND("]",CELL("filename",C5))+1,255)&"_"&$B$12&"'!H"&ROW(C6)) -> 1 | P16: =INDIRECT("'[CILA2_Validation_Files.xlsx]"&$A$2&"_"&$M$3&"_"&COLUMN(D$2)*100&"k_"&MID(CELL("filename",D5),FIND("]",CELL("filename",D5))+1,255)&"_"&$B$12&"'!H"&ROW(D6)) -> 1 | Q16: =INDIRECT("'[CILA2_Validation_Files.xlsx]"&$A$2&"_"&$M$3&"_"&COLUMN(E$2)*100&"k_"&MID(CELL("filename",E5),FIND("]",CELL("filename",E5))+1,255)&"_"&$B$12&"'!H"&ROW(E6)) -> 1 | R16: =INDIRECT("'[CILA2_Validation_Files.xlsx]"&$A$2&"_"&$R$3&"_"&COLUMN(A$2)*100&"k_"&MID(CELL("filename",A5),FIND("]",CELL("filename",A5))+1,255)&"_"&$B$12&"'!H"&ROW(A6)) -> 0 | S16: =INDIRECT("'[CILA2_Validation_Files.xlsx]"&$A$2&"_"&$R$3&"_"&COLUMN(B$2)*100&"k_"&MID(CELL("filename",B5),FIND("]",CELL("filename",B5))+1,255)&"_"&$B$12&"'!H"&ROW(B6)) -> 1 | T16: =INDIRECT("'[CILA2_Validation_Files.xlsx]"&$A$2&"_"&$R$3&"_"&COLUMN(C$2)*100&"k_"&MID(CELL("filename",C5),FIND("]",CELL("filename",C5))+1,255)&"_"&$B$12&"'!H"&ROW(C6)) -> 1 | U16: =INDIRECT("'[CILA2_Validation_Files.xlsx]"&$A$2&"_"&$R$3&"_"&COLUMN(D$2)*100&"k_"&MID(CELL("filename",D5),FIND("]",CELL("filename",D5))+1,255)&"_"&$B$12&"'!H"&ROW(D6)) -> 1 | V16: =INDIRECT("'[CILA2_Validation_Files.xlsx]"&$A$2&"_"&$R$3&"_"&COLUMN(E$2)*100&"k_"&MID(CELL("filename",E5),FIND("]",CELL("filename",E5))+1,255)&"_"&$B$12&"'!H"&ROW(E6)) -> 0 | W16: =INDIRECT("'[CILA2_Validation_Files.xlsx]"&$A$2&"_"&$W$3&"_"&COLUMN(A$2)*100&"k_"&MID(CELL("filename",A5),FIND("]",CELL("filename",A5))+1,255)&"_"&$B$12&"'!H"&ROW(A6)) -> 1 | X16: =INDIRECT("'[CILA2_Validation_Files.xlsx]"&$A$2&"_"&$W$3&"_"&COLUMN(B$2)*100&"k_"&MID(CELL("filename",B5),FIND("]",CELL("filename",B5))+1,255)&"_"&$B$12&"'!H"&ROW(B6)) -> 1 | Y16: =INDIRECT("'[CILA2_Validation_Files.xlsx]"&$A$2&"_"&$W$3&"_"&COLUMN(C$2)*100&"k_"&MID(CELL("filename",C5),FIND("]",CELL("filename",C5))+1,255)&"_"&$B$12&"'!H"&ROW(C6)) -> 1 | Z16: =INDIRECT("'[CILA2_Validation_Files.xlsx]"&$A$2&"_"&$W$3&"_"&COLUMN(D$2)*100&"k_"&MID(CELL("filename",D5),FIND("]",CELL("filename",D5))+1,255)&"_"&$B$12&"'!H"&ROW(D6)) -> 0 | AA16: =INDIRECT("'[CILA2_Validation_Files.xlsx]"&$A$2&"_"&$W$3&"_"&COLUMN(E$2)*100&"k_"&MID(CELL("filename",E5),FIND("]",CELL("filename",E5))+1,255)&"_"&$B$12&"'!H"&ROW(E6)) -> 1
A17: 12 | C17: =INDIRECT("'[CILA2_Validation_Files.xlsx]"&$A$2&"_"&$C$3&"_"&COLUMN(A$2)*100&"k_"&MID(CELL("filename",A6),FIND("]",CELL("filename",A6))+1,255)&"_"&$B$12&"'!H"&ROW(A7)) -> 0 | D17: =INDIRECT("'[CILA2_Validation_Files.xlsx]"&$A$2&"_"&$C$3&"_"&COLUMN(B$2)*100&"k_"&MID(CELL("filename",B6),FIND("]",CELL("filename",B6))+1,255)&"_"&$B$12&"'!H"&ROW(B7)) -> 1 | E17: =INDIRECT("'[CILA2_Validation_Files.xlsx]"&$A$2&"_"&$C$3&"_"&COLUMN(C$2)*100&"k_"&MID(CELL("filename",C6),FIND("]",CELL("filename",C6))+1,255)&"_"&$B$12&"'!H"&ROW(C7)) -> 1 | F17: =INDIRECT("'[CILA2_Validation_Files.xlsx]"&$A$2&"_"&$C$3&"_"&COLUMN(D$2)*100&"k_"&MID(CELL("filename",D6),FIND("]",CELL("filename",D6))+1,255)&"_"&$B$12&"'!H"&ROW(D7)) -> 1 | G17: =INDIRECT("'[CILA2_Validation_Files.xlsx]"&$A$2&"_"&$C$3&"_"&COLUMN(E$2)*100&"k_"&MID(CELL("filename",E6),FIND("]",CELL("filename",E6))+1,255)&"_"&$B$12&"'!H"&ROW(E7)) -> 1 | H17: =INDIRECT("'[CILA2_Validation_Files.xlsx]"&$A$2&"_"&$H$3&"_"&COLUMN(A$2)*100&"k_"&MID(CELL("filename",A6),FIND("]",CELL("filename",A6))+1,255)&"_"&$B$12&"'!H"&ROW(A7)) -> 1 | I17: =INDIRECT("'[CILA2_Validation_Files.xlsx]"&$A$2&"_"&$H$3&"_"&COLUMN(B$2)*100&"k_"&MID(CELL("filename",B6),FIND("]",CELL("filename",B6))+1,255)&"_"&$B$12&"'!H"&ROW(B7)) -> 1 | J17: =INDIRECT("'[CILA2_Validation_Files.xlsx]"&$A$2&"_"&$H$3&"_"&COLUMN(C$2)*100&"k_"&MID(CELL("filename",C6),FIND("]",CELL("filename",C6))+1,255)&"_"&$B$12&"'!H"&ROW(C7)) -> 1 | K17: =INDIRECT("'[CILA2_Validation_Files.xlsx]"&$A$2&"_"&$H$3&"_"&COLUMN(D$2)*100&"k_"&MID(CELL("filename",D6),FIND("]",CELL("filename",D6))+1,255)&"_"&$B$12&"'!H"&ROW(D7)) -> 0 | L17: =INDIRECT("'[CILA2_Validation_Files.xlsx]"&$A$2&"_"&$H$3&"_"&COLUMN(E$2)*100&"k_"&MID(CELL("filename",E6),FIND("]",CELL("filename",E6))+1,255)&"_"&$B$12&"'!H"&ROW(E7)) -> 1 | M17: =INDIRECT("'[CILA2_Validation_Files.xlsx]"&$A$2&"_"&$M$3&"_"&COLUMN(A$2)*100&"k_"&MID(CELL("filename",A6),FIND("]",CELL("filename",A6))+1,255)&"_"&$B$12&"'!H"&ROW(A7)) -> 1 | N17: =INDIRECT("'[CILA2_Validation_Files.xlsx]"&$A$2&"_"&$M$3&"_"&COLUMN(B$2)*100&"k_"&MID(CELL("filename",B6),FIND("]",CELL("filename",B6))+1,255)&"_"&$B$12&"'!H"&ROW(B7)) -> 1 | O17: =INDIRECT("'[CILA2_Validation_Files.xlsx]"&$A$2&"_"&$M$3&"_"&COLUMN(C$2)*100&"k_"&MID(CELL("filename",C6),FIND("]",CELL("filename",C6))+1,255)&"_"&$B$12&"'!H"&ROW(C7)) -> 1 | P17: =INDIRECT("'[CILA2_Validation_Files.xlsx]"&$A$2&"_"&$M$3&"_"&COLUMN(D$2)*100&"k_"&MID(CELL("filename",D6),FIND("]",CELL("filename",D6))+1,255)&"_"&$B$12&"'!H"&ROW(D7)) -> 1 | Q17: =INDIRECT("'[CILA2_Validation_Files.xlsx]"&$A$2&"_"&$M$3&"_"&COLUMN(E$2)*100&"k_"&MID(CELL("filename",E6),FIND("]",CELL("filename",E6))+1,255)&"_"&$B$12&"'!H"&ROW(E7)) -> 1 | R17: =INDIRECT("'[CILA2_Validation_Files.xlsx]"&$A$2&"_"&$R$3&"_"&COLUMN(A$2)*100&"k_"&MID(CELL("filename",A6),FIND("]",CELL("filename",A6))+1,255)&"_"&$B$12&"'!H"&ROW(A7)) -> 0 | S17: =INDIRECT("'[CILA2_Validation_Files.xlsx]"&$A$2&"_"&$R$3&"_"&COLUMN(B$2)*100&"k_"&MID(CELL("filename",B6),FIND("]",CELL("filename",B6))+1,255)&"_"&$B$12&"'!H"&ROW(B7)) -> 1 | T17: =INDIRECT("'[CILA2_Validation_Files.xlsx]"&$A$2&"_"&$R$3&"_"&COLUMN(C$2)*100&"k_"&MID(CELL("filename",C6),FIND("]",CELL("filename",C6))+1,255)&"_"&$B$12&"'!H"&ROW(C7)) -> 1 | U17: =INDIRECT("'[CILA2_Validation_Files.xlsx]"&$A$2&"_"&$R$3&"_"&COLUMN(D$2)*100&"k_"&MID(CELL("filename",D6),FIND("]",CELL("filename",D6))+1,255)&"_"&$B$12&"'!H"&ROW(D7)) -> 1 | V17: =INDIRECT("'[CILA2_Validation_Files.xlsx]"&$A$2&"_"&$R$3&"_"&COLUMN(E$2)*100&"k_"&MID(CELL("filename",E6),FIND("]",CELL("filename",E6))+1,255)&"_"&$B$12&"'!H"&ROW(E7)) -> 1 | W17: =INDIRECT("'[CILA2_Validation_Files.xlsx]"&$A$2&"_"&$W$3&"_"&COLUMN(A$2)*100&"k_"&MID(CELL("filename",A6),FIND("]",CELL("filename",A6))+1,255)&"_"&$B$12&"'!H"&ROW(A7)) -> 1 | X17: =INDIRECT("'[CILA2_Validation_Files.xlsx]"&$A$2&"_"&$W$3&"_"&COLUMN(B$2)*100&"k_"&MID(CELL("filename",B6),FIND("]",CELL("filename",B6))+1,255)&"_"&$B$12&"'!H"&ROW(B7)) -> 1 | Y17: =INDIRECT("'[CILA2_Validation_Files.xlsx]"&$A$2&"_"&$W$3&"_"&COLUMN(C$2)*100&"k_"&MID(CELL("filename",C6),FIND("]",CELL("filename",C6))+1,255)&"_"&$B$12&"'!H"&ROW(C7)) -> 1 | Z17: =INDIRECT("'[CILA2_Validation_Files.xlsx]"&$A$2&"_"&$W$3&"_"&COLUMN(D$2)*100&"k_"&MID(CELL("filename",D6),FIND("]",CELL("filename",D6))+1,255)&"_"&$B$12&"'!H"&ROW(D7)) -> 1 | AA17: =INDIRECT("'[CILA2_Validation_Files.xlsx]"&$A$2&"_"&$W$3&"_"&COLUMN(E$2)*100&"k_"&MID(CELL("filename",E6),FIND("]",CELL("filename",E6))+1,255)&"_"&$B$12&"'!H"&ROW(E7)) -> 1
A18: 13 | B18: navigation | C18: =INDIRECT("'[CILA2_Validation_Files.xlsx]"&$A$2&"_"&$C$3&"_"&COLUMN(A$2)*100&"k_"&MID(CELL("filename",A1),FIND("]",CELL("filename",A1))+1,255)&"_"&$B$18&"'!H"&ROW(A2)) -> 0 | D18: =INDIRECT("'[CILA2_Validation_Files.xlsx]"&$A$2&"_"&$C$3&"_"&COLUMN(B$2)*100&"k_"&MID(CELL("filename",B1),FIND("]",CELL("filename",B1))+1,255)&"_"&$B$18&"'!H"&ROW(B2)) -> 1 | E18: =INDIRECT("'[CILA2_Validation_Files.xlsx]"&$A$2&"_"&$C$3&"_"&COLUMN(C$2)*100&"k_"&MID(CELL("filename",C1),FIND("]",CELL("filename",C1))+1,255)&"_"&$B$18&"'!H"&ROW(C2)) -> 1 | F18: =INDIRECT("'[CILA2_Validation_Files.xlsx]"&$A$2&"_"&$C$3&"_"&COLUMN(D$2)*100&"k_"&MID(CELL("filename",D1),FIND("]",CELL("filename",D1))+1,255)&"_"&$B$18&"'!H"&ROW(D2)) -> 1 | G18: =INDIRECT("'[CILA2_Validation_Files.xlsx]"&$A$2&"_"&$C$3&"_"&COLUMN(E$2)*100&"k_"&MID(CELL("filename",E1),FIND("]",CELL("filename",E1))+1,255)&"_"&$B$18&"'!H"&ROW(E2)) -> 1 | H18: =INDIRECT("'[CILA2_Validation_Files.xlsx]"&$A$2&"_"&$H$3&"_"&COLUMN(A$2)*100&"k_"&MID(CELL("filename",A1),FIND("]",CELL("filename",A1))+1,255)&"_"&$B$18&"'!H"&ROW(A2)) -> 1 | I18: =INDIRECT("'[CILA2_Validation_Files.xlsx]"&$A$2&"_"&$H$3&"_"&COLUMN(B$2)*100&"k_"&MID(CELL("filename",B1),FIND("]",CELL("filename",B1))+1,255)&"_"&$B$18&"'!H"&ROW(B2)) -> 1 | J18: =INDIRECT("'[CILA2_Validation_Files.xlsx]"&$A$2&"_"&$H$3&"_"&COLUMN(C$2)*100&"k_"&MID(CELL("filename",C1),FIND("]",CELL("filename",C1))+1,255)&"_"&$B$18&"'!H"&ROW(C2)) -> 1 | K18: =INDIRECT("'[CILA2_Validation_Files.xlsx]"&$A$2&"_"&$H$3&"_"&COLUMN(D$2)*100&"k_"&MID(CELL("filename",D1),FIND("]",CELL("filename",D1))+1,255)&"_"&$B$18&"'!H"&ROW(D2)) -> 0 | L18: =INDIRECT("'[CILA2_Validation_Files.xlsx]"&$A$2&"_"&$H$3&"_"&COLUMN(E$2)*100&"k_"&MID(CELL("filename",E1),FIND("]",CELL("filename",E1))+1,255)&"_"&$B$18&"'!H"&ROW(E2)) -> 1 | M18: =INDIRECT("'[CILA2_Validation_Files.xlsx]"&$A$2&"_"&$M$3&"_"&COLUMN(A$2)*100&"k_"&MID(CELL("filename",A1),FIND("]",CELL("filename",A1))+1,255)&"_"&$B$18&"'!H"&ROW(A2)) -> 1 | N18: =INDIRECT("'[CILA2_Validation_Files.xlsx]"&$A$2&"_"&$M$3&"_"&COLUMN(B$2)*100&"k_"&MID(CELL("filename",B1),FIND("]",CELL("filename",B1))+1,255)&"_"&$B$18&"'!H"&ROW(B2)) -> 1 | O18: =INDIRECT("'[CILA2_Validation_Files.xlsx]"&$A$2&"_"&$M$3&"_"&COLUMN(C$2)*100&"k_"&MID(CELL("filename",C1),FIND("]",CELL("filename",C1))+1,255)&"_"&$B$18&"'!H"&ROW(C2)) -> 1 | P18: =INDIRECT("'[CILA2_Validation_Files.xlsx]"&$A$2&"_"&$M$3&"_"&COLUMN(D$2)*100&"k_"&MID(CELL("filename",D1),FIND("]",CELL("filename",D1))+1,255)&"_"&$B$18&"'!H"&ROW(D2)) -> 1 | Q18: =INDIRECT("'[CILA2_Validation_Files.xlsx]"&$A$2&"_"&$M$3&"_"&COLUMN(E$2)*100&"k_"&MID(CELL("filename",E1),FIND("]",CELL("filename",E1))+1,255)&"_"&$B$18&"'!H"&ROW(E2)) -> 1 | R18: =INDIRECT("'[CILA2_Validation_Files.xlsx]"&$A$2&"_"&$R$3&"_"&COLUMN(A$2)*100&"k_"&MID(CELL("filename",A1),FIND("]",CELL("filename",A1))+1,255)&"_"&$B$18&"'!H"&ROW(A2)) -> 0 | S18: =INDIRECT("'[CILA2_Validation_Files.xlsx]"&$A$2&"_"&$R$3&"_"&COLUMN(B$2)*100&"k_"&MID(CELL("filename",B1),FIND("]",CELL("filename",B1))+1,255)&"_"&$B$18&"'!H"&ROW(B2)) -> 1 | T18: =INDIRECT("'[CILA2_Validation_Files.xlsx]"&$A$2&"_"&$R$3&"_"&COLUMN(C$2)*100&"k_"&MID(CELL("filename",C1),FIND("]",CELL("filename",C1))+1,255)&"_"&$B$18&"'!H"&ROW(C2)) -> 1 | U18: =INDIRECT("'[CILA2_Validation_Files.xlsx]"&$A$2&"_"&$R$3&"_"&COLUMN(D$2)*100&"k_"&MID(CELL("filename",D1),FIND("]",CELL("filename",D1))+1,255)&"_"&$B$18&"'!H"&ROW(D2)) -> 1 | V18: =INDIRECT("'[CILA2_Validation_Files.xlsx]"&$A$2&"_"&$R$3&"_"&COLUMN(E$2)*100&"k_"&MID(CELL("filename",E1),FIND("]",CELL("filename",E1))+1,255)&"_"&$B$18&"'!H"&ROW(E2)) -> 1 | W18: =INDIRECT("'[CILA2_Validation_Files.xlsx]"&$A$2&"_"&$W$3&"_"&COLUMN(A$2)*100&"k_"&MID(CELL("filename",A1),FIND("]",CELL("filename",A1))+1,255)&"_"&$B$18&"'!H"&ROW(A2)) -> 1 | X18: =INDIRECT("'[CILA2_Validation_Files.xlsx]"&$A$2&"_"&$W$3&"_"&COLUMN(B$2)*100&"k_"&MID(CELL("filename",B1),FIND("]",CELL("filename",B1))+1,255)&"_"&$B$18&"'!H"&ROW(B2)) -> 0 | Y18: =INDIRECT("'[CILA2_Validation_Files.xlsx]"&$A$2&"_"&$W$3&"_"&COLUMN(C$2)*100&"k_"&MID(CELL("filename",C1),FIND("]",CELL("filename",C1))+1,255)&"_"&$B$18&"'!H"&ROW(C2)) -> 0 | Z18: =INDIRECT("'[CILA2_Validation_Files.xlsx]"&$A$2&"_"&$W$3&"_"&COLUMN(D$2)*100&"k_"&MID(CELL("filename",D1),FIND("]",CELL("filename",D1))+1,255)&"_"&$B$18&"'!H"&ROW(D2)) -> 0 | AA18: =INDIRECT("'[CILA2_Validation_Files.xlsx]"&$A$2&"_"&$W$3&"_"&COLUMN(E$2)*100&"k_"&MID(CELL("filename",E1),FIND("]",CELL("filename",E1))+1,255)&"_"&$B$18&"'!H"&ROW(E2)) -> 1 | AB18: =AVERAGE(C18:AA23) -> 0.7
